Workbook

Sheet 26년 5월
C1: ◎ 스테리케어 손익 결산 (부가세별도가 기준)
H2: 2026년 (귀속월 기준)
C3: 대분류 | D3: 중분류 | E3: 소분류 | F3: 상대거래처 | G3: 상세내역 | H3: 1월 | I3: 1월 비율계상 (%) | J3: 2월 | K3: 2월 비율계상 (%) | L3: 3월 | M3: 3월 비율계상 (%) | N3: 1분기 합계 | O3: 1분기 비율계상 (%) | P3: 4월 | Q3: 4월 비율계상 (%) | R3: 5월 | S3: 5월 비율계상 (%) | T3: 6월 | U3: 6월 비율계상 (%) | V3: 2분기 합계 | W3: 2분기 비율계상 (%) | X3: 7월 | Y3: 7월 비율계상 (%) | Z3: 8월 | AA3: 8월 비율계상 (%) | AB3: 9월 | AC3: 9월 비율계상 (%) | AD3: 3분기 합계 | AE3: 3분기 비율계상 (%) | AF3: 10월 | AG3: 10월 비율계상 (%) | AH3: 11월 | AI3: 11월 비율계상 (%) | AJ3: 12월 | AK3: 12월 비율계상 (%) | AL3: 4분기 합계 | AM3: 4분기 비율계상 (%) | AN3: 2026년 합계 | AO3: 비고
C4: 매출원가 | D4: 서비스매출원가 | E4: 가운원가 | F4: 부천세종병원 | G4: 가운원가반영 | H4: ='월별원가(류)5월'!Q11 -> 1298904.5 | I4: =H4/H11 -> 0.040444379 | J4: ='월별원가(류)5월'!R11 -> 1029270.9 | K4: =J4/J11 -> 0.03687823 | L4: ='월별원가(류)5월'!S11 -> 1021823.6 | M4: =L4/L11 -> 0.03310279 | N4: =SUM(H4,J4,L4) -> 3349999.1 | O4: =N4/N11 -> 0.036856102 | P4: ='월별원가(류)5월'!T11 -> 1202576.4 | Q4: =P4/P11 -> 0.038145629 | R4: ='월별원가(류)5월'!U11 -> 927198.18 | S4: =R4/R11 -> 0.034085681 | U4: =T4/T11 -> #DIV/0! | V4: =SUM(P4,R4,T4) -> 2129774.5 | W4: =V4/V$27 -> 0.010967051 | Y4: =X4/X11 -> #DIV/0! | AA4: =Z4/Z11 -> #DIV/0! | AC4: =AB4/AB11 -> #DIV/0! | AD4: =SUM(X4,Z4,AB4) -> 0 | AE4: =AD4/AD$27 -> #DIV/0! | AG4: =AF4/AF11 -> #DIV/0! | AI4: =AH4/AH11 -> #DIV/0! | AK4: =AJ4/AJ11 -> #DIV/0! | AL4: =SUM(AF4,AH4,AJ4) -> 0 | AM4: =AL4/AL$27 -> #DIV/0! | AN4: =SUM(AD4,V4,N4,AL4) -> 5479773.6
C5: 매출원가 | D5: 서비스매출원가 | E5: 가운원가 | F5: 인천세종병원 | G5: 가운원가반영 | H5: ='월별원가(류)5월'!Q19 -> 1631721.8 | I5: =H5/H16 -> 0.044456817 | J5: ='월별원가(류)5월'!R19 -> 1289300.9 | K5: =J5/J16 -> 0.041560373 | L5: ='월별원가(류)5월'!S19 -> 1459183.6 | M5: =L5/L16 -> 0.040488366 | N5: =SUM(H5,J5,L5) -> 4380206.4 | O5: =N5/N16 -> 0.042212566 | P5: ='월별원가(류)5월'!T19 -> 1459327.3 | Q5: =P5/P16 -> 0.039821982 | R5: ='월별원가(류)5월'!U19 -> 1316907.3 | S5: =R5/R16 -> 0.039420615 | U5: =T5/T16 -> #DIV/0! | V5: =SUM(P5,R5,T5) -> 2776234.5 | W5: =V5/V$27 -> 0.014295929 | Y5: =X5/X16 -> #DIV/0! | AA5: =Z5/Z16 -> #DIV/0! | AC5: =AB5/AB16 -> #DIV/0! | AD5: =SUM(X5,Z5,AB5) -> 0 | AE5: =AD5/AD$27 -> #DIV/0! | AG5: =AF5/AF16 -> #DIV/0! | AI5: =AH5/AH16 -> #DIV/0! | AK5: =AJ5/AJ16 -> #DIV/0! | AL5: =SUM(AF5,AH5,AJ5) -> 0 | AM5: =AL5/AL$27 -> #DIV/0! | AN5: =SUM(AD5,V5,N5,AL5) -> 7156440.9
B6: 가운 원가 합계 | H6: =SUM(H4:H5) -> 2930626.4 | I6: =H6/H27 -> 0.034547478 | J6: =SUM(J4:J5) -> 2318571.8 | K6: =J6/J27 -> 0.031432881 | L6: =SUM(L4:L5) -> 2481007.3 | M6: =L6/L27 -> 0.024404956 | N6: =SUM(H6,J6,L6) -> 7730205.5 | O6: =N6/N27 -> 0.029702821 | P6: =SUM(P4:P5) -> 2661903.6 | Q6: =P6/P27 -> 0.026076823 | R6: =SUM(R4:R5) -> 2244105.5 | S6: =R6/R27 -> 0.024361133 | T6: =SUM(T4:T5) -> 0 | U6: =T6/T27 -> #DIV/0! | V6: =SUM(P6,R6,T6) -> 4906009.1 | W6: =V6/V$27 -> 0.02526298 | X6: =SUM(X4:X5) -> 0 | Y6: =X6/X27 -> #DIV/0! | Z6: =SUM(Z4:Z5) -> 0 | AA6: =Z6/Z27 -> #DIV/0! | AB6: =SUM(AB4:AB5) -> 0 | AC6: =AB6/AB27 -> #DIV/0! | AD6: =SUM(X6,Z6,AB6) -> 0 | AE6: =AD6/AD$27 -> #DIV/0! | AF6: =SUM(AF4:AF5) -> 0 | AG6: =AF6/AF27 -> #DIV/0! | AH6: =SUM(AH4:AH5) -> 0 | AI6: =AH6/AH27 -> #DIV/0! | AJ6: =SUM(AJ4:AJ5) -> 0 | AK6: =AJ6/AJ27 -> #DIV/0! | AL6: =SUM(AF6,AH6,AJ6) -> 0 | AM6: =AL6/AL$27 -> #DIV/0! | AN6: =SUM(AN4:AN5) -> 12636215
C7: 매출 | D7: 서비스매출 | E7: 서비스매출 | F7: 부천세종병원 | G7: 일반세탁물 | H7: 26032869 | I7: =H7/H$27 -> 0.3068866 | J7: 23030641 | K7: =J7/J$27 -> 0.31222643 | L7: 25936284 | M7: =L7/L$27 -> 0.25512778 | N7: =SUM(H7,J7,L7) -> 74999794 | O7: =N7/$N$27 -> 0.28818193 | P7: 25857801 | Q7: =P7/$P$27 -> 0.25331094 | R7: 22822321 | S7: =R7/$R$27 -> 0.24775021 | U7: =T7/$T$27 -> #DIV/0! | V7: =SUM(P7,R7,T7) -> 48680122 | W7: =V7/V$27 -> 0.25067319 | Y7: =X7/X$27 -> #DIV/0! | AA7: =Z7/Z$27 -> #DIV/0! | AC7: =AB7/AB$27 -> #DIV/0! | AD7: =SUM(X7,Z7,AB7) -> 0 | AE7: =AD7/AD$27 -> #DIV/0! | AG7: =AF7/AF$27 -> #DIV/0! | AI7: =AH7/AH$27 -> #DIV/0! | AK7: =AJ7/AJ$27 -> #DIV/0! | AL7: =SUM(AF7,AH7,AJ7) -> 0 | AM7: =AL7/AL$27 -> #DIV/0! | AN7: =SUM(N7+V7+AD7+AL7) -> 123679916
C8: 매출 | D8: 서비스매출 | E8: 서비스매출 | G8: 렌탈가운_멸균 | H8: 4792500 | I8: =H8/H$27 -> 0.056496041 | J8: 3709800 | K8: =J8/J$27 -> 0.050293764 | L8: 3612600 | M8: =L8/L$27 -> 0.035536109 | N8: =SUM(H8,J8,L8) -> 12114900 | O8: =N8/$N$27 -> 0.046550731 | P8: 4325400 | Q8: =P8/$P$27 -> 0.042372943 | R8: 3385800 | S8: =R8/$R$27 -> 0.036754924 | U8: =T8/$T$27 -> #DIV/0! | V8: =SUM(P8,R8,T8) -> 7711200 | W8: =V8/V$27 -> 0.039708017 | Y8: =X8/X$27 -> #DIV/0! | AA8: =Z8/Z$27 -> #DIV/0! | AC8: =AB8/AB$27 -> #DIV/0! | AD8: =SUM(X8,Z8,AB8) -> 0 | AE8: =AD8/AD$27 -> #DIV/0! | AG8: =AF8/AF$27 -> #DIV/0! | AI8: =AH8/AH$27 -> #DIV/0! | AK8: =AJ8/AJ$27 -> #DIV/0! | AL8: =SUM(AF8,AH8,AJ8) -> 0 | AM8: =AL8/AL$27 -> #DIV/0! | AN8: =SUM(N8+V8+AD8+AL8) -> 19826100
C9: 매출 | D9: 서비스매출 | E9: 서비스매출 | G9: 렌탈가운_비멸균 | H9: 271364 | I9: =H9/H$27 -> 0.003198955 | J9: 271364 | K9: =J9/J$27 -> 0.0036788821 | L9: 282955 | M9: =L9/L$27 -> 0.0027833471 | N9: =SUM(H9,J9,L9) -> 825683 | O9: =N9/$N$27 -> 0.0031726343 | P9: 444545 | Q9: =P9/$P$27 -> 0.0043548989 | R9: 233864 | S9: =R9/$R$27 -> 0.0025387363 | U9: =T9/$T$27 -> #DIV/0! | V9: =SUM(P9,R9,T9) -> 678409 | W9: =V9/V$27 -> 0.0034933961 | Y9: =X9/X$27 -> #DIV/0! | AA9: =Z9/Z$27 -> #DIV/0! | AC9: =AB9/AB$27 -> #DIV/0! | AD9: =SUM(X9,Z9,AB9) -> 0 | AE9: =AD9/AD$27 -> #DIV/0! | AG9: =AF9/AF$27 -> #DIV/0! | AI9: =AH9/AH$27 -> #DIV/0! | AK9: =AJ9/AJ$27 -> #DIV/0! | AL9: =SUM(AF9,AH9,AJ9) -> 0 | AM9: =AL9/AL$27 -> #DIV/0! | AN9: =SUM(N9+V9+AD9+AL9) -> 1504092
C10: 매출 | D10: 서비스매출 | E10: 서비스매출 | G10: 렌탈 멸균 프로텍트커버 | H10: 1019091 | I10: =H10/H$27 -> 0.012013481 | J10: 898182 | K10: =J10/J$27 -> 0.012176655 | L10: 1036364 | M10: =L10/L$27 -> 0.010194415 | N10: =SUM(H10,J10,L10) -> 2953637 | O10: =N10/$N$27 -> 0.011349162 | P10: 898182 | Q10: =P10/$P$27 -> 0.0087988659 | R10: 760000 | S10: =R10/$R$27 -> 0.0082502635 | U10: =T10/$T$27 -> #DIV/0! | V10: =SUM(P10,R10,T10) -> 1658182 | W10: =V10/V$27 -> 0.0085386345 | Y10: =X10/X$27 -> #DIV/0! | AA10: =Z10/Z$27 -> #DIV/0! | AC10: =AB10/AB$27 -> #DIV/0! | AD10: =SUM(X10,Z10,AB10) -> 0 | AE10: =AD10/AD$27 -> #DIV/0! | AG10: =AF10/AF$27 -> #DIV/0! | AI10: =AH10/AH$27 -> #DIV/0! | AK10: =AJ10/AJ$27 -> #DIV/0! | AL10: =SUM(AF10,AH10,AJ10) -> 0 | AM10: =AL10/AL$27 -> #DIV/0! | AN10: =SUM(N10+V10+AD10+AL10) -> 4611819
C11: 매출 | D11: 서비스매출 | E11: 서비스매출 | G11: 부천세종병원 매출 합계 | H11: =SUM(H7:H10) -> 32115824 | I11: =H11/H$27 -> 0.37859508 | J11: =SUM(J7:J10) -> 27909987 | K11: =J11/J$27 -> 0.37837573 | L11: =SUM(L7:L10) -> 30868203 | M11: =L11/L$27 -> 0.30364165 | N11: =SUM(H11,J11,L11) -> 90894014 | O11: =N11/$N$27 -> 0.34925445 | P11: =SUM(P7:P10) -> 31525928 | Q11: =P11/P27 -> 0.30883764 | R11: =SUM(R7:R10) -> 27201985 | S11: =R11/R27 -> 0.29529414 | T11: =SUM(T7:T10) -> 0 | U11: =T11/T27 -> #DIV/0! | V11: =SUM(P11,R11,T11) -> 58727913 | W11: =V11/V$27 -> 0.30241324 | X11: =SUM(X7:X10) -> 0 | Y11: =X11/X27 -> #DIV/0! | Z11: =SUM(Z7:Z10) -> 0 | AA11: =Z11/Z27 -> #DIV/0! | AB11: =SUM(AB7:AB10) -> 0 | AC11: =AB11/AB27 -> #DIV/0! | AD11: =SUM(X11,Z11,AB11) -> 0 | AE11: =AD11/AD$27 -> #DIV/0! | AF11: =SUM(AF7:AF10) -> 0 | AG11: =AF11/AF27 -> #DIV/0! | AH11: =SUM(AH7:AH10) -> 0 | AI11: =AH11/AH27 -> #DIV/0! | AJ11: =SUM(AJ7:AJ10) -> 0 | AK11: =AJ11/AJ27 -> #DIV/0! | AL11: =SUM(AF11,AH11,AJ11) -> 0 | AM11: =AL11/AL$27 -> #DIV/0! | AN11: =SUM(AN7:AN10) -> 149621927 | AP11: =R11+R16+R22+R24+R26 -> 92118270
C12: 매출 | D12: 서비스매출 | E12: 서비스매출 | F12: 인천세종병원 | G12: 일반세탁물 | H12: 29669531 | I12: =H12/H$27 -> 0.34975713 | J12: 25419534 | K12: =J12/J$27 -> 0.34461266 | L12: 29658333 | M12: =L12/L$27 -> 0.2917405 | N12: =SUM(H12,J12,L12) -> 84747398 | O12: =N12/$N$27 -> 0.32563647 | P12: 30195047 | Q12: =P12/$P$27 -> 0.29579993 | R12: 27783036 | S12: =R12/$R$27 -> 0.3016018 | U12: =T12/$T$27 -> #DIV/0! | V12: =SUM(P12,R12,T12) -> 57978083 | W12: =V12/V$27 -> 0.29855206 | Y12: =X12/X$27 -> #DIV/0! | AA12: =Z12/Z$27 -> #DIV/0! | AC12: =AB12/AB$27 -> #DIV/0! | AD12: =SUM(X12,Z12,AB12) -> 0 | AE12: =AD12/AD$27 -> #DIV/0! | AG12: =AF12/AF$27 -> #DIV/0! | AI12: =AH12/AH$27 -> #DIV/0! | AK12: =AJ12/AJ$27 -> #DIV/0! | AL12: =SUM(AF12,AH12,AJ12) -> 0 | AM12: =AL12/AL$27 -> #DIV/0! | AN12: =SUM(AD12,V12,N12,AL12) -> 142725481
C13: 매출 | D13: 서비스매출 | E13: 서비스매출 | G13: 렌탈가운_멸균 | H13: 6107400 | I13: =H13/H$27 -> 0.071996645 | J13: 4760100 | K13: =J13/J$27 -> 0.064532682 | L13: 5524200 | M13: =L13/L$27 -> 0.054339969 | N13: =SUM(H13,J13,L13) -> 16391700 | O13: =N13/$N$27 -> 0.062984062 | P13: 5346000 | Q13: =P13/$P$27 -> 0.052371053 | R13: 5005800 | S13: =R13/$R$27 -> 0.054341012 | U13: =T13/$T$27 -> #DIV/0! | V13: =SUM(P13,R13,T13) -> 10351800 | W13: =V13/V$27 -> 0.05330551 | Y13: =X13/X$27 -> #DIV/0! | AA13: =Z13/Z$27 -> #DIV/0! | AC13: =AB13/AB$27 -> #DIV/0! | AD13: =SUM(X13,Z13,AB13) -> 0 | AE13: =AD13/AD$27 -> #DIV/0! | AG13: =AF13/AF$27 -> #DIV/0! | AI13: =AH13/AH$27 -> #DIV/0! | AK13: =AJ13/AJ$27 -> #DIV/0! | AL13: =SUM(AF13,AH13,AJ13) -> 0 | AM13: =AL13/AL$27 -> #DIV/0! | AN13: =SUM(N13+V13+AD13+AL13) -> 26743500
C14: 매출 | D14: 서비스매출 | E14: 서비스매출 | G14: 렌탈가운_비멸균 | H14: 926592 | I14: =H14/H$27 -> 0.010923063 | J14: 842727 | K14: =J14/J$27 -> 0.011424851 | L14: 857045 | M14: =L14/L$27 -> 0.0084305055 | N14: =SUM(H14,J14,L14) -> 2626364 | O14: =N14/$N$27 -> 0.010091636 | P14: 1105227 | Q14: =P14/$P$27 -> 0.010827142 | R14: 617727 | S14: =R14/$R$27 -> 0.0067058033 | U14: =T14/$T$27 -> #DIV/0! | V14: =SUM(P14,R14,T14) -> 1722954 | W14: =V14/V$27 -> 0.0088721711 | Y14: =X14/X$27 -> #DIV/0! | AA14: =Z14/Z$27 -> #DIV/0! | AC14: =AB14/AB$27 -> #DIV/0! | AD14: =SUM(X14,Z14,AB14) -> 0 | AE14: =AD14/AD$27 -> #DIV/0! | AG14: =AF14/AF$27 -> #DIV/0! | AI14: =AH14/AH$27 -> #DIV/0! | AK14: =AJ14/AJ$27 -> #DIV/0! | AL14: =SUM(AF14,AH14,AJ14) -> 0 | AM14: =AL14/AL$27 -> #DIV/0! | AN14: =SUM(N14+V14+AD14+AL14) -> 4349318
C15: 매출 | D15: 서비스매출 | E15: 서비스매출 | G15: 렌탈 멸균 프로텍트커버 | H15: 0 | I15: =H15/H$27 -> 0 | J15: 0 | K15: =J15/J$27 -> 0 | L15: 0 | M15: =L15/L$27 -> 0 | N15: =SUM(H15,J15,L15) -> 0 | O15: =N15/$N$27 -> 0 | P15: 0 | Q15: =P15/$P$27 -> 0 | R15: 0 | S15: =R15/$R$27 -> 0 | U15: =T15/$T$27 -> #DIV/0! | V15: =SUM(P15,R15,T15) -> 0 | W15: =V15/V$27 -> 0 | Y15: =X15/X$27 -> #DIV/0! | AA15: =Z15/Z$27 -> #DIV/0! | AC15: =AB15/AB$27 -> #DIV/0! | AD15: =SUM(X15,Z15,AB15) -> 0 | AE15: =AD15/AD$27 -> #DIV/0! | AG15: =AF15/AF$27 -> #DIV/0! | AI15: =AH15/AH$27 -> #DIV/0! | AK15: =AJ15/AJ$27 -> #DIV/0! | AL15: =SUM(AF15,AH15,AJ15) -> 0 | AM15: =AL15/AL$27 -> #DIV/0! | AN15: =SUM(N15+V15+AD15+AL15) -> 0
C16: 매출 | D16: 서비스매출 | E16: 서비스매출 | G16: 인천세종병원 매출 합계 | H16: =SUM(H12:H15) -> 36703523 | I16: =H16/H$27 -> 0.43267684 | J16: =SUM(J12:J15) -> 31022361 | K16: =J16/J$27 -> 0.42057019 | L16: =SUM(L12:L15) -> 36039578 | M16: =L16/L$27 -> 0.35451098 | N16: =SUM(H16,J16,L16) -> 103765462 | O16: =N16/$N$27 -> 0.39871217 | P16: =SUM(P12:P15) -> 36646274 | Q16: =P16/$P$27 -> 0.35899812 | R16: =SUM(R12:R15) -> 33406563 | S16: =R16/$R$27 -> 0.36264861 | T16: =SUM(T12:T15) -> 0 | U16: =T16/$T$27 -> #DIV/0! | V16: =SUM(P16,R16,T16) -> 70052837 | W16: =V16/V$27 -> 0.36072974 | X16: =SUM(X12:X15) -> 0 | Y16: =X16/X27 -> #DIV/0! | Z16: =SUM(Z12:Z15) -> 0 | AA16: =Z16/Z27 -> #DIV/0! | AB16: =SUM(AB12:AB15) -> 0 | AC16: =AB16/AB27 -> #DIV/0! | AD16: =SUM(X16,Z16,AB16) -> 0 | AE16: =AD16/AD$27 -> #DIV/0! | AF16: =SUM(AF12:AF15) -> 0 | AG16: =AF16/AF27 -> #DIV/0! | AH16: =SUM(AH12:AH15) -> 0 | AI16: =AH16/AH27 -> #DIV/0! | AJ16: =SUM(AJ12:AJ15) -> 0 | AK16: =AJ16/AJ27 -> #DIV/0! | AL16: =SUM(AF16,AH16,AJ16) -> 0 | AM16: =AL16/AL$27 -> #DIV/0! | AN16: =SUM(AN12:AN15) -> 173818299
C17: 매출 | D17: 서비스매출 | E17: 서비스매출 | F17: 메디탁 | G17: 일반세탁물(허균) | H17: 1500000 | I17: =H17/H$27 -> 0.017682642 | J17: 1500000 | K17: =J17/J$27 -> 0.020335502 | L17: 0 | M17: =L17/L$27 -> 0 | N17: =SUM(H17,J17,L17) -> 3000000 | O17: =N17/N$27 -> 0.011527309 | P17: 0 | Q17: =P17/P$27 -> 0 | R17: 0 | S17: =R17/R$27 -> 0 | T17: 0 | U17: =T17/T$27 -> #DIV/0! | V17: =SUM(P17,R17,T17) -> 0 | W17: =V17/V$27 -> 0 | X17: 0 | Y17: =X17/X$27 -> #DIV/0! | Z17: 0 | AA17: =Z17/Z$27 -> #DIV/0! | AB17: 0 | AC17: =AB17/AB$27 -> #DIV/0! | AD17: =SUM(X17,Z17,AB17) -> 0 | AE17: =AD17/AD$27 -> #DIV/0! | AF17: 0 | AG17: =AF17/AF$27 -> #DIV/0! | AH17: 0 | AI17: =AH17/AH$27 -> #DIV/0! | AJ17: 0 | AK17: =AJ17/AJ$27 -> #DIV/0! | AL17: =SUM(AF17,AH17,AJ17) -> 0 | AM17: =AL17/AL$27 -> #DIV/0! | AN17: =SUM(N17+V17+AD17+AL17) -> 3000000
C18: 매출 | D18: 서비스매출 | E18: 서비스매출 | G18: 일반세탁물(나움) | H18: 880000 | I18: =H18/H$27 -> 0.010373817 | J18: 880000 | K18: =J18/J$27 -> 0.011930161 | L18: 0 | M18: =L18/L$27 -> 0 | N18: =SUM(H18,J18,L18) -> 1760000 | O18: =N18/N$27 -> 0.0067626878 | P18: 0 | Q18: =P18/P$27 -> 0 | R18: 0 | S18: =R18/R$27 -> 0 | T18: 0 | U18: =T18/T$27 -> #DIV/0! | V18: =SUM(P18,R18,T18) -> 0 | W18: =V18/V$27 -> 0 | X18: 0 | Y18: =X18/X$27 -> #DIV/0! | Z18: 0 | AA18: =Z18/Z$27 -> #DIV/0! | AB18: 0 | AC18: =AB18/AB$27 -> #DIV/0! | AD18: =SUM(X18,Z18,AB18) -> 0 | AE18: =AD18/AD$27 -> #DIV/0! | AF18: 0 | AG18: =AF18/AF$27 -> #DIV/0! | AH18: 0 | AI18: =AH18/AH$27 -> #DIV/0! | AJ18: 0 | AK18: =AJ18/AJ$27 -> #DIV/0! | AL18: =SUM(AF18,AH18,AJ18) -> 0 | AM18: =AL18/AL$27 -> #DIV/0! | AN18: =SUM(N18+V18+AD18+AL18) -> 1760000
C19: 매출 | D19: 서비스매출 | E19: 서비스매출 | G19: 일반세탁물(강서바른) | H19: 1745455 | I19: =H19/H$27 -> 0.02057617 | J19: 1745454.4 | K19: =J19/J$27 -> 0.023663128 | L19: 0 | M19: =L19/L$27 -> 0 | N19: =SUM(H19,J19,L19) -> 3490909.4 | O19: =N19/N$27 -> 0.013413597 | P19: 0 | Q19: =P19/P$27 -> 0 | R19: 0 | S19: =R19/R$27 -> 0 | T19: 0 | U19: =T19/T$27 -> #DIV/0! | V19: =SUM(P19,R19,T19) -> 0 | W19: =V19/V$27 -> 0 | X19: 0 | Y19: =X19/X$27 -> #DIV/0! | Z19: 0 | AA19: =Z19/Z$27 -> #DIV/0! | AB19: 0 | AC19: =AB19/AB$27 -> #DIV/0! | AD19: =SUM(X19,Z19,AB19) -> 0 | AE19: =AD19/AD$27 -> #DIV/0! | AF19: 0 | AG19: =AF19/AF$27 -> #DIV/0! | AH19: 0 | AI19: =AH19/AH$27 -> #DIV/0! | AJ19: 0 | AK19: =AJ19/AJ$27 -> #DIV/0! | AL19: =SUM(AF19,AH19,AJ19) -> 0 | AM19: =AL19/AL$27 -> #DIV/0! | AN19: =SUM(N19+V19+AD19+AL19) -> 3490909.4
C20: 매출 | D20: 서비스매출 | E20: 서비스매출 | G20: 메디탁 매출 합계 | H20: =SUM(H17:H19) -> 4125455 | I20: =H20/H$27 -> 0.048632629 | J20: =SUM(J17:J19) -> 4125454.4 | K20: =J20/J$27 -> 0.055928791 | L20: =SUM(L17:L19) -> 0 | M20: =L20/L$27 -> 0 | N20: =SUM(H20,J20,L20) -> 8250909.4 | O20: =N20/N$27 -> 0.031703593 | P20: =SUM(P17:P19) -> 0 | Q20: =P$20/P$27 -> 0 | R20: =SUM(R17:R19) -> 0 | S20: =R$20/R$27 -> 0 | T20: =SUM(T17:T19) -> 0 | U20: =T$20/T$27 -> #DIV/0! | V20: =SUM(P20,R20,T20) -> 0 | X20: =SUM(X17:X19) -> 0 | Y20: =X$20/X$27 -> #DIV/0! | Z20: =SUM(Z17:Z19) -> 0 | AA20: =Z$20/Z$27 -> #DIV/0! | AB20: =SUM(AB17:AB19) -> 0 | AC20: =AB$20/AB$27 -> #DIV/0! | AD20: =SUM(X20,Z20,AB20) -> 0 | AF20: =SUM(AF17:AF19) -> 0 | AG20: =AF$20/AF$27 -> #DIV/0! | AH20: =SUM(AH17:AH19) -> 0 | AI20: =AH$20/AH$27 -> #DIV/0! | AJ20: =SUM(AJ17:AJ19) -> 0 | AK20: =AJ$20/AJ$27 -> #DIV/0! | AL20: =SUM(AF20,AH20,AJ20) -> 0 | AN20: =SUM(AN17:AN19) -> 8250909.4
C21: 매출 | D21: 서비스매출 | E21: 서비스매출 | F21: 파주병원 | G21: 일반세탁물 | H21: 11884151 | I21: =H21/H$27 -> 0.14009546 | J21: 10213913 | K21: =J21/J$27 -> 0.13847003 | L21: 11649696 | M21: =L21/L$27 -> 0.11459471 | N21: =SUM(H21,J21,L21) -> 33747760 | O21: =N21/N$27 -> 0.12967362 | P21: 11331338 | Q21: =P21/P$27 -> 0.11100526 | R21: 9893187 | S21: =R21/R$27 -> 0.10739658 | U21: =T21/T$27 -> #DIV/0! | V21: =SUM(P21,R21,T21) -> 21224525 | W21: =V21/V$27 -> 0.10929347 | Y21: =X21/X$27 -> #DIV/0! | AA21: =Z21/Z$27 -> #DIV/0! | AC21: =AB21/AB$27 -> #DIV/0! | AD21: =SUM(X21,Z21,AB21) -> 0 | AE21: =AD21/AD$27 -> #DIV/0! | AG21: =AF21/AF$27 -> #DIV/0! | AI21: =AH21/AH$27 -> #DIV/0! | AK21: =AJ21/AJ$27 -> #DIV/0! | AL21: =SUM(AF21,AH21,AJ21) -> 0 | AM21: =AL21/AL$27 -> #DIV/0! | AN21: =SUM(N21+V21+AD21+AL21) -> 54972285
C22: 매출 | D22: 서비스매출 | E22: 서비스매출 | G22: 파주병원 매출 합계 | H22: =SUM(H21) -> 11884151 | I22: =H22/H$27 -> 0.14009546 | J22: =SUM(J21) -> 10213913 | K22: =J22/J$27 -> 0.13847003 | L22: =SUM(L21) -> 11649696 | M22: =L22/L$27 -> 0.11459471 | N22: =SUM(H22,J22,L22) -> 33747760 | O22: =N22/N$27 -> 0.12967362 | P22: =SUM(P21) -> 11331338 | Q22: =P$20/P$27 -> 0 | R22: =SUM(R21) -> 9893187 | S22: =R$20/R$27 -> 0 | T22: =SUM(T21) -> 0 | U22: =T$20/T$27 -> #DIV/0! | V22: =SUM(P22,R22,T22) -> 21224525 | X22: =SUM(X21) -> 0 | Y22: =X$20/X$27 -> #DIV/0! | Z22: =SUM(Z21) -> 0 | AA22: =Z$20/Z$27 -> #DIV/0! | AB22: =SUM(AB21) -> 0 | AC22: =AB$20/AB$27 -> #DIV/0! | AD22: =SUM(X22,Z22,AB22) -> 0 | AF22: =SUM(AF21) -> 0 | AG22: =AF$20/AF$27 -> #DIV/0! | AH22: =SUM(AH21) -> 0 | AI22: =AH$20/AH$27 -> #DIV/0! | AJ22: =SUM(AJ21) -> 0 | AK22: =AJ$20/AJ$27 -> #DIV/0! | AL22: =SUM(AF22,AH22,AJ22) -> 0 | AN22: =SUM(AN21) -> 54972285
C23: 매출 | D23: 서비스매출 | E23: 서비스매출 | F23: 일산중심재활병원 | G23: 일반세탁물 | H23: 0 | I23: =H23/H$27 -> 0 | J23: 490909 | K23: =J23/J$27 -> 0.006655254 | L23: =4818182+490909 -> 5309091 | M23: =L23/L$27 -> 0.052224004 | N23: =SUM(H23,J23,L23) -> 5800000 | O23: =N23/N$27 -> 0.02228613 | P23: 4818182 | Q23: =P23/P$27 -> 0.047200386 | R23: 4818182 | S23: =R23/R$27 -> 0.052304304 | U23: =T23/T$27 -> #DIV/0! | V23: =SUM(P23,R23,T23) -> 9636364 | W23: =V23/V$27 -> 0.049621447 | Y23: =X23/X$27 -> #DIV/0! | AA23: =Z23/Z$27 -> #DIV/0! | AC23: =AB23/AB$27 -> #DIV/0! | AD23: =SUM(X23,Z23,AB23) -> 0 | AE23: =AD23/AD$27 -> #DIV/0! | AG23: =AF23/AF$27 -> #DIV/0! | AI23: =AH23/AH$27 -> #DIV/0! | AK23: =AJ23/AJ$27 -> #DIV/0! | AL23: =SUM(AF23,AH23,AJ23) -> 0 | AM23: =AL23/AL$27 -> #DIV/0! | AN23: =SUM(N23+V23+AD23+AL23) -> 15436364
C24: 매출 | D24: 서비스매출 | E24: 서비스매출 | G24: 일산중심재활병원 매출 합계 | H24: =SUM(H23) -> 0 | I24: =H24/H$27 -> 0 | J24: =SUM(J23) -> 490909 | K24: =J24/J$27 -> 0.006655254 | L24: =SUM(L23) -> 5309091 | M24: =L24/L$27 -> 0.052224004 | N24: =SUM(H24,J24,L24) -> 5800000 | O24: =N24/N$27 -> 0.02228613 | P24: =SUM(P23) -> 4818182 | Q24: =P$20/P$27 -> 0 | R24: =SUM(R23) -> 4818182 | S24: =R$20/R$27 -> 0 | T24: =SUM(T23) -> 0 | U24: =T$20/T$27 -> #DIV/0! | V24: =SUM(P24,R24,T24) -> 9636364 | X24: =SUM(X23) -> 0 | Y24: =X$20/X$27 -> #DIV/0! | Z24: =SUM(Z23) -> 0 | AA24: =Z$20/Z$27 -> #DIV/0! | AB24: =SUM(AB23) -> 0 | AC24: =AB$20/AB$27 -> #DIV/0! | AD24: =SUM(X24,Z24,AB24) -> 0 | AF24: =SUM(AF23) -> 0 | AG24: =AF$20/AF$27 -> #DIV/0! | AH24: =SUM(AH23) -> 0 | AI24: =AH$20/AH$27 -> #DIV/0! | AJ24: =SUM(AJ23) -> 0 | AK24: =AJ$20/AJ$27 -> #DIV/0! | AL24: =SUM(AF24,AH24,AJ24) -> 0 | AN24: =SUM(AN23) -> 15436364
C25: 매출 | D25: 서비스매출 | E25: 서비스매출 | F25: 뉴고려병원 | G25: 일반세탁물 | H25: 0 | I25: =H25/H$27 -> 0 | J25: 0 | K25: =J25/J$27 -> 0 | L25: 17793409 | M25: =L25/L$27 -> 0.17502865 | N25: =SUM(H25,J25,L25) -> 17793409 | O25: =N25/N$27 -> 0.068370039 | P25: 17757570 | Q25: =P25/P$27 -> 0.17395859 | R25: 16798353 | S25: =R25/R$27 -> 0.18235637 | U25: =T25/T$27 -> #DIV/0! | V25: =SUM(P25,R25,T25) -> 34555923 | W25: =V25/V$27 -> 0.17794211 | Y25: =X25/X$27 -> #DIV/0! | AA25: =Z25/Z$27 -> #DIV/0! | AC25: =AB25/AB$27 -> #DIV/0! | AD25: =SUM(X25,Z25,AB25) -> 0 | AE25: =AD25/AD$27 -> #DIV/0! | AG25: =AF25/AF$27 -> #DIV/0! | AI25: =AH25/AH$27 -> #DIV/0! | AK25: =AJ25/AJ$27 -> #DIV/0! | AL25: =SUM(AF25,AH25,AJ25) -> 0 | AM25: =AL25/AL$27 -> #DIV/0! | AN25: =SUM(N25+V25+AD25+AL25) -> 52349332
C26: 매출 | D26: 서비스매출 | E26: 서비스매출 | G26: 뉴고려병원 매출 합계 | H26: =SUM(H25) -> 0 | I26: =H26/H$27 -> 0 | J26: =SUM(J25) -> 0 | K26: =J26/J$27 -> 0 | L26: =SUM(L25) -> 17793409 | M26: =L26/L$27 -> 0.17502865 | N26: =SUM(H26,J26,L26) -> 17793409 | O26: =N26/N$27 -> 0.068370039 | P26: =SUM(P25) -> 17757570 | Q26: =P$20/P$27 -> 0 | R26: =SUM(R25) -> 16798353 | S26: =R$20/R$27 -> 0 | T26: =SUM(T25) -> 0 | U26: =T$20/T$27 -> #DIV/0! | V26: =SUM(P26,R26,T26) -> 34555923 | X26: =SUM(X25) -> 0 | Y26: =X$20/X$27 -> #DIV/0! | Z26: =SUM(Z25) -> 0 | AA26: =Z$20/Z$27 -> #DIV/0! | AB26: =SUM(AB25) -> 0 | AC26: =AB$20/AB$27 -> #DIV/0! | AD26: =SUM(X26,Z26,AB26) -> 0 | AF26: =SUM(AF25) -> 0 | AG26: =AF$20/AF$27 -> #DIV/0! | AH26: =SUM(AH25) -> 0 | AI26: =AH$20/AH$27 -> #DIV/0! | AJ26: =SUM(AJ25) -> 0 | AK26: =AJ$20/AJ$27 -> #DIV/0! | AL26: =SUM(AF26,AH26,AJ26) -> 0 | AN26: =SUM(AN25) -> 52349332
B27: 스테리케어 매출 합계액 (부가세 별도가 기준) | H27: =H16+H11+H20+H22+H24+H26 -> 84828953 | I27: =I16+I11+I20+I22+I24+I26 -> 1 | J27: =J16+J11+J20+J22+J24+J26 -> 73762624 | K27: =K16+K11+K20+K22+K24+K26 -> 1 | L27: =L16+L11+L20+L22+L24+L26 -> 101659977 | M27: =M16+M11+M20+M22+M24+M26 -> 1 | N27: =SUM(H27,J27,L27) -> 2.6025155e+08 | O27: =O16+O11+O20+O22+O24+O26 -> 1 | P27: =P16+P11+P20+P22+P24+P26 -> 102079292 | Q27: =Q16+Q11+Q20+Q22+Q24+Q26 -> 0.66783576 | R27: =R16+R11+R20+R22+R24+R26 -> 92118270 | S27: =S16+S11+S20+S22+S24+S26 -> 0.65794275 | T27: =T16+T11+T20+T22+T24+T26 -> 0 | U27: =U16+U11+U20+U22+U24+U26 -> #DIV/0! | V27: =SUM(P27,R27,T27) -> 194197562 | W27: =W16+W11+W20+W22+W24+W26 -> 0.66314298 | X27: =X16+X11+X20+X22+X24+X26 -> 0 | Y27: =Y16+Y11+Y20+Y22+Y24+Y26 -> #DIV/0! | Z27: =Z16+Z11+Z20+Z22+Z24+Z26 -> 0 | AA27: =AA16+AA11+AA20+AA22+AA24+AA26 -> #DIV/0! | AB27: =AB16+AB11+AB20+AB22+AB24+AB26 -> 0 | AC27: =AC16+AC11+AC20+AC22+AC24+AC26 -> #DIV/0! | AD27: =SUM(X27,Z27,AB27) -> 0 | AE27: =AE16+AE11+AE20+AE22+AE24+AE26 -> #DIV/0! | AF27: =AF16+AF11+AF20+AF22+AF24+AF26 -> 0 | AG27: =AG16+AG11+AG20+AG22+AG24+AG26 -> #DIV/0! | AH27: =AH16+AH11+AH20+AH22+AH24+AH26 -> 0 | AI27: =AI16+AI11+AI20+AI22+AI24+AI26 -> #DIV/0! | AJ27: =AJ16+AJ11+AJ20+AJ22+AJ24+AJ26 -> 0 | AK27: =AK16+AK11+AK20+AK22+AK24+AK26 -> #DIV/0! | AL27: =SUM(AF27,AH27,AJ27) -> 0 | AM27: =AM16+AM11+AM20+AM22+AM24+AM26 -> #DIV/0! | AN27: =AN16+AN11+AN20+AN22+AN24+AN26 -> 4.5444912e+08
C28: 노무비 | D28: 상시근로자 | E28: 직원급여 | F28: 전계룡 | G28: 스테리케어 총괄 이사 (9/23 입사) | H28: 4166660 | J28: 4166660 | L28: 4166660 | N28: =SUM(H28,J28,L28) -> 12499980 | P28: 3333330 | R28: 0 | V28: =SUM(P28,R28,T28) -> 3333330 | AD28: =SUM(X28,Z28,AB28) -> 0 | AL28: =SUM(AF28,AH28,AJ28) -> 0 | AN28: =SUM(AD28,V28,N28,AL28) -> 15833310
C29: 노무비 | D29: 상시근로자 | E29: 직원급여 | F29: 박우생 | G29: 생산총괄팀장 | H29: 5000000 | J29: 5000000 | L29: 5198090 | N29: =SUM(H29,J29,L29) -> 15198090 | P29: 5000000 | R29: 5185330 | V29: =SUM(P29,R29,T29) -> 10185330 | AD29: =SUM(X29,Z29,AB29) -> 0 | AL29: =SUM(AF29,AH29,AJ29) -> 0 | AN29: =SUM(AD29,V29,N29,AL29) -> 25383420
C30: 노무비 | D30: 상시근로자 | E30: 직원급여 | F30: 김진빈 | G30: 26.04.07 입사 (중간관리자) | H30: 0 | J30: 0 | L30: 0 | N30: =SUM(H30,J30,L30) -> 0 | P30: 2527500 | R30: 3525780 | V30: =SUM(P30,R30,T30) -> 6053280 | AD30: =SUM(X30,Z30,AB30) -> 0 | AL30: =SUM(AF30,AH30,AJ30) -> 0 | AN30: =SUM(AD30,V30,N30,AL30) -> 6053280
C31: 노무비 | D31: 상시근로자 | E31: 직원급여 | F31: 권혁 | G31: 24.06.17 입사 (중간관리자) | H31: 3416660 | J31: 3416660 | L31: 3536740 | N31: =SUM(H31,J31,L31) -> 10370060 | P31: 1138880 | R31: 0 | V31: =SUM(P31,R31,T31) -> 1138880 | AD31: =SUM(X31,Z31,AB31) -> 0 | AL31: =SUM(AF31,AH31,AJ31) -> 0 | AN31: =SUM(AD31,V31,N31,AL31) -> 11508940
C32: 노무비 | D32: 상시근로자 | E32: 직원급여 | F32: 김하나 | G32: 정리포장 주임 (5/06 입사) | H32: 3450000 | J32: 3450000 | L32: 3550620 | N32: =SUM(H32,J32,L32) -> 10450620 | P32: 3450000 | R32: 3527400 | V32: =SUM(P32,R32,T32) -> 6977400 | AD32: =SUM(X32,Z32,AB32) -> 0 | AL32: =SUM(AF32,AH32,AJ32) -> 0 | AN32: =SUM(AD32,V32,N32,AL32) -> 17428020
C33: 노무비 | D33: 상시근로자 | E33: 직원급여 | F33: 김계순 | G33: 23.06.15 입사 (멸균실 정리포장) | H33: 2489700 | J33: 2551620 | L33: 2559360 | N33: =SUM(H33,J33,L33) -> 7600680 | P33: 2342640 | R33: 2543880 | V33: =SUM(P33,R33,T33) -> 4886520 | AD33: =SUM(X33,Z33,AB33) -> 0 | AL33: =SUM(AF33,AH33,AJ33) -> 0 | AN33: =SUM(AD33,V33,N33,AL33) -> 12487200
C34: 노무비 | D34: 상시근로자 | E34: 직원급여 | F34: 박정란 | G34: 멸균실 정리포장 (중국) H2 | H34: 2427780 | J34: 2551620 | L34: 2435520 | N34: =SUM(H34,J34,L34) -> 7414920 | P34: 2404560 | R34: 2779640 | V34: =SUM(P34,R34,T34) -> 5184200 | AD34: =SUM(X34,Z34,AB34) -> 0 | AL34: =SUM(AF34,AH34,AJ34) -> 0 | AN34: =SUM(AD34,V34,N34,AL34) -> 12599120
C35: 노무비 | D35: 상시근로자 | E35: 직원급여 | F35: 고호성 | G35: 24.10.29 입사 (정리포장) | H35: 2427780 | J35: 2543880 | L35: 2342640 | N35: =SUM(H35,J35,L35) -> 7314300 | P35: 2280720 | R35: 2605800 | V35: =SUM(P35,R35,T35) -> 4886520 | AD35: =SUM(X35,Z35,AB35) -> 0 | AL35: =SUM(AF35,AH35,AJ35) -> 0 | AN35: =SUM(AD35,V35,N35,AL35) -> 12200820
C36: 노무비 | D36: 상시근로자 | E36: 직원급여 | F36: 강낙순 | G36: 25.05.02 입사 (정리포장) | H36: 2303940 | J36: 2543880 | L36: 2288460 | N36: =SUM(H36,J36,L36) -> 7136280 | P36: 2280720 | R36: 2404560 | V36: =SUM(P36,R36,T36) -> 4685280 | AD36: =SUM(X36,Z36,AB36) -> 0 | AL36: =SUM(AF36,AH36,AJ36) -> 0 | AN36: =SUM(AD36,V36,N36,AL36) -> 11821560
C37: 노무비 | D37: 상시근로자 | E37: 직원급여 | F37: 수실 | G37: 25.05.19 입사 | H37: 3500000 | J37: 2767080 | L37: 2648380 | N37: =SUM(H37,J37,L37) -> 8915460 | P37: 2500000 | R37: 2745120 | V37: =SUM(P37,R37,T37) -> 5245120 | AD37: =SUM(X37,Z37,AB37) -> 0 | AL37: =SUM(AF37,AH37,AJ37) -> 0 | AN37: =SUM(AD37,V37,N37,AL37) -> 14160580
C38: 노무비 | D38: 상시근로자 | E38: 직원급여 | F38: 다라_BHATTA TARA | G38: 25.10.20 입사 (포장) G1 > 25.11.14(체류자격활동허가 처리후 서류상 입사일) | H38: 2839700 | J38: 2543880 | L38: 2412300 | N38: =SUM(H38,J38,L38) -> 7795880 | P38: 2342640 | R38: 2605800 | V38: =SUM(P38,R38,T38) -> 4948440 | AD38: =SUM(X38,Z38,AB38) -> 0 | AL38: =SUM(AF38,AH38,AJ38) -> 0 | AN38: =SUM(AD38,V38,N38,AL38) -> 12744320
C39: 노무비 | D39: 상시근로자 | E39: 직원급여 | F39: 바크누아_SALYKBAYEV BAKNUR | G39: 25.10.27 입사 (건조) G1 > 25.12.11 (체류자격활동허가 처리후 서류상 입사일) | H39: 2700000 | J39: 2829000 | L39: 2700000 | N39: =SUM(H39,J39,L39) -> 8229000 | P39: 2700000 | R39: 2891330 | V39: =SUM(P39,R39,T39) -> 5591330 | AD39: =SUM(X39,Z39,AB39) -> 0 | AL39: =SUM(AF39,AH39,AJ39) -> 0 | AN39: =SUM(AD39,V39,N39,AL39) -> 13820330
... C48: 노무비 | D48: 상시근로자 | E48: 직원급여 | F48: 박풍화_PIAO FENGHUA | G48: 2026.05.18 입사 (정리포장) | H48: 0 | J48: 0 | L48: 0 | N48: =SUM(H48,J48,L48) -> 0 | P48: 0 | R48: 990720 | V48: =SUM(P48,R48,T48) -> 990720 | AD48: =SUM(X48,Z48,AB48) -> 0 | AL48: =SUM(AF48,AH48,AJ48) -> 0 | AN48: =SUM(AD48,V48,N48,AL48) -> 990720
...

Sheet 주요비율산정표(%)
B2: ◎ 스테리케어 매출액 대비 주요 비율 산정표
K4: 보고일 : 2025-08-13
C5: 대분류 | D5: 중분류 | E5: 소분류 | F5: 상대거래처 | G5: 상세내역 | H5: 1월 | I5: 2월 | J5: 3월 | K5: 1분기 합계 | L5: 1분기 비율계상 (%) | M5: 4월 | N5: 4월 비율계상 (%) | O5: 5월 | P5: 5월 비율계상 (%) | Q5: 6월 | R5: 6월 비율계상 (%) | S5: 2분기 합계 | T5: 2분기 비율계상 (%) | U5: 7월 | V5: 7월 비율계상 (%) | W5: 8월 | X5: 8월 비율계상 (%) | Y5: 9월 | Z5: 9월 비율계상 (%) | AA5: 3분기 합계 | AB5: 3분기 비율계상 (%) | AC5: 10월 | AD5: 10월 비율계상 (%) | AE5: 11월 | AF5: 11월 비율계상 (%) | AG5: 12월 | AH5: 12월 비율계상 (%) | AI5: 4분기 합계 | AJ5: 2025년 합계
B6: 1 | C6: 매출 | D6: 서비스매출 | E6: 서비스매출 | F6: 인천세종병원 | G6: 일반세탁물 | H6: =26437209/1.1 -> 24033826 | I6: =24858650/1.1 -> 22598773 | J6: =26871649/1.1 -> 24428772 | K6: =SUM(H6:J6) -> 71061371 | L6: =K6/$K$20 -> 0.42263467 | M6: 26823809 | N6: =M6/$M$20 -> 0.41687678 | O6: 23911793 | P6: =O6/$O$20 -> 0.42051506 | Q6: 27962143 | R6: =Q6/$Q$20 -> 0.4320372 | S6: =M6+O6+Q6 -> 78697745 | T6: =S6/$S$20 -> 0.42326679 | U6: 32399302 | V6: =U6/$U$20 -> 0.43850199 | W6: 28922248 | X6: =W6/W$20 -> 0.43640741 | Y6: 32211285 | Z6: =Y6/Y$20 -> 0.43657955 | AA6: =SUM(U6+W6+Y6) -> 93532835 | AB6: =AA6/AA$20 -> 0.43719016 | AC6: 27161257 | AD6: =AC6/AC$20 -> 0.428958 | AE6: 28023935 | AF6: =AE6/AE$20 -> 0.42484326 | AG6: 31133762 | AH6: =AG6/AG$20 -> 0.40506105 | AI6: =SUM(AC6+AE6+AG6) -> 86318954 | AJ6: =SUM(AA6,S6,K6,AI6) -> 3.296109e+08 | AK6: =AJ6-#REF! -> #REF!
G7: 렌탈가운_멸균 | H7: =6228090/1.1 -> 5661900 | I7: =5452920/1.1 -> 4957200 | J7: =6430050/1.1 -> 5845500 | K7: =SUM(H7:J7) -> 16464600 | L7: =K7/$K$20 -> 0.097922552 | M7: 5977800 | N7: =M7/$M$20 -> 0.092902764 | O7: 5346000 | P7: =O7/$O$20 -> 0.094015262 | Q7: 5278500 | R7: =Q7/$Q$20 -> 0.081556996 | S7: =M7+O7+Q7 -> 16602300 | T7: =S7/$S$20 -> 0.089293565 | U7: 5896800 | V7: =U7/$U$20 -> 0.079809081 | W7: 5540400 | X7: =W7/W$20 -> 0.083599021 | Y7: 5732100 | Z7: =Y7/Y$20 -> 0.077690711 | AA7: =SUM(U7+W7+Y7) -> 17169300 | AB7: =AA7/AA$20 -> 0.080252555 | AC7: 5086800 | AD7: =AC7/AC$20 -> 0.080335883 | AE7: 5005800 | AF7: =AE7/AE$20 -> 0.075888001 | AG7: 5556600 | AH7: =AG7/AG$20 -> 0.072293294 | AI7: =SUM(AC7+AE7+AG7) -> 15649200 | AJ7: =SUM(AA7,S7,K7,AI7) -> 65885400 | AK7: =AJ7-#REF! -> #REF!
G8: 렌탈가운_비멸균 | H8: =1146000/1.1 -> 1041818.2 | I8: =1403250/1.1-1 -> 1275680.8 | J8: =749250/1.1 -> 681136.36 | K8: =SUM(H8:J8) -> 2998635.4 | L8: =K8/$K$20 -> 0.017834264 | M8: 1336364 | N8: =M8/$M$20 -> 0.02076883 | O8: 1200682 | P8: =O8/$O$20 -> 0.021115307 | Q8: 1001591 | R8: =Q8/$Q$20 -> 0.015475372 | S8: =M8+O8+Q8 -> 3538637 | T8: =S8/$S$20 -> 0.019032153 | U8: 1076591 | V8: =U8/$U$20 -> 0.014570909 | W8: 1088182 | X8: =W8/W$20 -> 0.016419564 | Y8: 1197955 | Z8: =Y8/Y$20 -> 0.016236628 | AA8: =SUM(U8+W8+Y8) -> 3362728 | AB8: =AA8/AA$20 -> 0.015718027 | AC8: 990000 | AD8: =AC8/AC$20 -> 0.01563508 | AE8: 952500 | AF8: =AE8/AE$20 -> 0.014439914 | AG8: 842727 | AH8: =AG8/AG$20 -> 0.010964171 | AI8: =SUM(AC8+AE8+AG8) -> 2785227 | AJ8: =SUM(AA8,S8,K8,AI8) -> 12685227 | AK8: =AJ8-#REF! -> #REF!
G9: 렌탈 멸균 프로텍트커버 | H9: 0 | I9: 0 | J9: 0 | K9: =SUM(H9:J9) -> 0 | L9: =K9/$K$20 -> 0 | M9: 207273 | N9: =M9/$M$20 -> 0.0032212912 | O9: 138182 | P9: =O9/$O$20 -> 0.0024300817 | Q9: 207273 | R9: =Q9/$Q$20 -> 0.0032025316 | S9: =M9+O9+Q9 -> 552728 | T9: =S9/$S$20 -> 0.0029727841 | U9: 69091 | V9: =U9/$U$20 -> 0.00093509856 | W9: 69091 | X9: =W9/W$20 -> 0.0010425132 | Y9: 0 | Z9: =Y9/Y$20 -> 0 | AA9: =SUM(U9+W9+Y9) -> 138182 | AB9: =AA9/AA$20 -> 0.0006458888 | AC9: 0 | AD9: =AC9/AC$20 -> 0 | AE9: 0 | AF9: =AE9/AE$20 -> 0 | AG9: 0 | AH9: =AG9/AG$20 -> 0 | AI9: =SUM(AC9+AE9+AG9) -> 0 | AJ9: =SUM(AA9,S9,K9,AI9) -> 690910 | AK9: =AJ9-#REF! -> #REF!
G10: 인천세종병원 매출 합계 | H10: =SUM(H6:H9) -> 30737545 | I10: =SUM(I6:I9) -> 28831654 | J10: =SUM(J6:J9) -> 30955408 | K10: =SUM(K6:K9) -> 90524606 | L10: =K10/$K$20 -> 0.53839149 | M10: =SUM(M6:M9) -> 34345246 | N10: =M10/$M$20 -> 0.53376966 | O10: =SUM(O6:O9) -> 30596657 | P10: =O10/$O$20 -> 0.53807571 | Q10: =SUM(Q6:Q9) -> 34449507 | R10: =Q10/$Q$20 -> 0.5322721 | S10: =SUM(S6:S9) -> 99391410 | T10: =S10/$S$20 -> 0.53456529 | U10: =SUM(U6:U9) -> 39441784 | V10: =U10/$U$20 -> 0.53381707 | W10: =SUM(W6:W9) -> 35619921 | X10: =W10/W$20 -> 0.53746851 | Y10: =SUM(Y6:Y9) -> 39141340 | Z10: =Y10/Y$20 -> 0.53050689 | AA10: =SUM(U10+W10+Y10) -> 114203045 | AB10: =AA10/$S$20 -> 0.61422797 | AC10: =SUM(AC6:AC9) -> 33238057 | AD10: =AC10/AC$20 -> 0.52492897 | AE10: =SUM(AE6:AE9) -> 33982235 | AF10: =AE10/AE$20 -> 0.51517118 | AG10: =SUM(AG6:AG9) -> 37533089 | AH10: =AG10/AG$20 -> 0.48831851 | AI10: =SUM(AI6:AI9) -> 104753381 | AJ10: =SUM(AA10,S10,K10,AI10) -> 4.0887244e+08 | AK10: =AJ10-#REF! -> #REF!
B11: 2 | F11: 부천세종병원 | G11: 일반세탁물 | H11: =23767165/1.1 -> 21606514 | I11: =22906077/1.1-1 -> 20823705 | J11: =23652433/1.1 -> 21502212 | K11: =SUM(H11:J11) -> 63932431 | L11: =K11/$K$20 -> 0.38023558 | M11: 23402595 | N11: =M11/$M$20 -> 0.36370667 | O11: 22005860 | P11: =O11/$O$20 -> 0.38699714 | Q11: 25043165 | R11: =Q11/$Q$20 -> 0.38693669 | S11: =M11+O11+Q11 -> 70451620 | T11: =S11/$S$20 -> 0.37891595 | U11: 28415082 | V11: =U11/$U$20 -> 0.38457834 | W11: 25286463 | X11: =W11/W$20 -> 0.3815471 | Y11: 28239172 | Z11: =Y11/Y$20 -> 0.38274304 | AA11: =SUM(U11+W11+Y11) -> 81940717 | AB11: =AA11/AA$20 -> 0.38300641 | AC11: 24024131 | AD11: =AC11/AC$20 -> 0.37941334 | AE11: 24285323 | AF11: =AE11/AE$20 -> 0.36816585 | AG11: 28932348 | AH11: =AG11/AG$20 -> 0.37641989 | AI11: =SUM(AC11+AE11+AG11) -> 77241802 | AJ11: =SUM(AA11,S11,K11,AI11) -> 2.9356657e+08 | AK11: =AJ11-#REF! -> #REF!
G12: 렌탈가운_멸균 | H12: =4235220/1.1 -> 3850200 | I12: =4757940/1.1 -> 4325400 | J12: =4232250/1.1 -> 3847500 | K12: =SUM(H12:J12) -> 12023100 | L12: =K12/$K$20 -> 0.071506908 | M12: 4608900 | N12: =M12/$M$20 -> 0.071628283 | O12: 3361500 | P12: =O12/$O$20 -> 0.059115657 | Q12: 3952800 | R12: =Q12/$Q$20 -> 0.061073883 | S12: =M12+O12+Q12 -> 11923200 | T12: =S12/$S$20 -> 0.064127563 | U12: 4260600 | V12: =U12/$U$20 -> 0.057664253 | W12: 3952800 | X12: =W12/W$20 -> 0.059643746 | Y12: 4179600 | Z12: =Y12/Y$20 -> 0.056648715 | AA12: =SUM(U12+W12+Y12) -> 12393000 | AB12: =AA12/AA$20 -> 0.057927225 | AC12: 3450600 | AD12: =AC12/AC$20 -> 0.05449536 | AE12: 3645000 | AF12: =AE12/AE$20 -> 0.055258253 | AG12: 4827600 | AH12: =AG12/AG$20 -> 0.062808751 | AI12: =SUM(AC12+AE12+AG12) -> 11923200 | AJ12: =SUM(AA12,S12,K12,AI12) -> 48262500 | AK12: =AJ12-#REF! -> #REF!
G13: 렌탈가운_비멸균 | H13: =660000/1.1 -> 600000 | I13: =577500/1.1 -> 525000 | J13: =533863 -> 533863 | K13: =SUM(H13:J13) -> 1658863 | L13: =K13/$K$20 -> 0.0098660216 | M13: 606136 | N13: =M13/$M$20 -> 0.0094201395 | O13: 346364 | P13: =O13/$O$20 -> 0.0060911901 | Q13: 308864 | R13: =Q13/$Q$20 -> 0.0047721929 | S13: =M13+O13+Q13 -> 1261364 | T13: =S13/$S$20 -> 0.0067841015 | U13: 456136 | V13: =U13/$U$20 -> 0.0061734831 | W13: 308864 | X13: =W13/W$20 -> 0.0046604448 | Y13: 444545 | Z13: =Y13/Y$20 -> 0.0060251945 | AA13: =SUM(U13+W13+Y13) -> 1209545 | AB13: =AA13/AA$20 -> 0.005653642 | AC13: 346364 | AD13: =AC13/AC$20 -> 0.0054701301 | AE13: 357955 | AF13: =AE13/AE$20 -> 0.005426603 | AG13: 407045 | AH13: =AG13/AG$20 -> 0.0052957967 | AI13: =SUM(AC13+AE13+AG13) -> 1111364 | AJ13: =SUM(AA13,S13,K13,AI13) -> 5241136 | AK13: =AJ13-#REF! -> #REF!
G14: 렌탈 멸균 프로텍트커버 | H14: 0 | I14: 0 | J14: 0 | K14: =SUM(H14:J14) -> 0 | L14: =K14/$K$20 -> 0 | M14: 1381818 | N14: =M14/$M$20 -> 0.021475244 | O14: 552727 | P14: =O14/$O$20 -> 0.0097203093 | Q14: 967273 | R14: =Q14/$Q$20 -> 0.014945132 | S14: =M14+O14+Q14 -> 2901818 | T14: =S14/$S$20 -> 0.015607095 | U14: 1312727 | V14: =U14/$U$20 -> 0.017766846 | W14: 1105455 | X14: =W14/W$20 -> 0.016680196 | Y14: 276364 | Z14: =Y14/Y$20 -> 0.0037457329 | AA14: =SUM(U14+W14+Y14) -> 2694546 | AB14: =AA14/AA$20 -> 0.012594818 | AC14: 760000 | AD14: =AC14/AC$20 -> 0.012002688 | AE14: 967273 | AF14: =AE14/AE$20 -> 0.014663873 | AG14: 1036364 | AH14: =AG14/AG$20 -> 0.013483455 | AI14: =SUM(AC14+AE14+AG14) -> 2763637 | AJ14: =SUM(AA14,S14,K14,AI14) -> 8360001 | AK14: =AJ14-#REF! -> #REF!
G15: 부천세종병원 매출 합계 | H15: =SUM(H11:H14) -> 26056714 | I15: =SUM(I11:I14) -> 25674105 | J15: =SUM(J11:J14) -> 25883575 | K15: =SUM(K11:K14) -> 77614394 | L15: =K15/$K$20 -> 0.46160851 | M15: =SUM(M11:M14) -> 29999449 | N15: =M15/$M$20 -> 0.46623034 | O15: =SUM(O11:O14) -> 26266451 | P15: =O15/$O$20 -> 0.46192429 | Q15: =SUM(Q11:Q14) -> 30272102 | R15: =Q15/$Q$20 -> 0.4677279 | S15: =SUM(S11:S14) -> 86538002 | T15: =S15/$S$20 -> 0.46543471 | U15: =SUM(U11:U14) -> 34444545 | V15: =U15/$U$20 -> 0.46618293 | W15: =SUM(W11:W14) -> 30653582 | X15: =W15/W$20 -> 0.46253149 | Y15: =SUM(Y11:Y14) -> 33139681 | Z15: =Y15/Y$20 -> 0.44916268 | AA15: =SUM(U15+W15+Y15) -> 98237808 | AB15: =AA15/$S$20 -> 0.52836077 | AC15: =SUM(AC11:AC14) -> 28581095 | AD15: =AC15/AC$20 -> 0.45138152 | AE15: =SUM(AE11:AE14) -> 29255551 | AF15: =AE15/AE$20 -> 0.44351458 | AG15: =SUM(AG11:AG14) -> 35203357 | AH15: =AG15/AG$20 -> 0.45800789 | AI15: =SUM(AI11:AI14) -> 93040003 | AJ15: =SUM(AA15,S15,K15,AI15) -> 3.5543021e+08 | AK15: =AJ15-#REF! -> #REF!
B16: 3 | F16: 메디탁 | G16: 일반세탁물(허균) | H16: 0 | I16: 0 | J16: 0 | K16: =SUM(H16:J16) -> 0 | L16: =K16/$K$20 -> 0 | M16: 0 | N16: =M16/$M$20 -> 0 | O16: 0 | P16: =O16/$O$20 -> 0 | Q16: 0 | R16: =Q16/$Q$20 -> 0 | S16: =M16+O16+Q16 -> 0 | T16: =S16/$S$20 -> 0 | U16: 0 | V16: =U16/$U$20 -> 0 | W16: 0 | X16: =W16/W$20 -> 0 | Y16: 1500000 | Z16: =Y16/Y$20 -> 0.020330432 | AA16: =SUM(U16+W16+Y16) -> 1500000 | AB16: =AA16/AA$20 -> 0.0070112836 | AC16: 1500000 | AD16: =AC16/AC$20 -> 0.023689515 | AE16: 1500000 | AF16: =AE16/AE$20 -> 0.022740022 | AG16: 1500000 | AH16: =AG16/AG$20 -> 0.019515521 | AI16: =SUM(AC16+AE16+AG16) -> 4500000 | AJ16: =SUM(AA16,S16,K16,AI16) -> 6000000 | AK16: =AJ16-#REF! -> #REF!
G17: 일반세탁물(나움) | K17: =SUM(H17:J17) -> 0 | N17: =M17/$M$20 -> 0 | P17: =O17/$O$20 -> 0 | R17: =Q17/$Q$20 -> 0 | S17: =M17+O17+Q17 -> 0 | T17: =S17/$S$20 -> 0 | V17: =U17/$U$20 -> 0 | X17: =W17/W$20 -> 0 | Y17: 0 | Z17: =Y17/Y$20 -> 0 | AA17: =SUM(U17+W17+Y17) -> 0 | AB17: =AA17/AA$20 -> 0 | AC17: 0 | AD17: =AC17/AC$20 -> 0 | AE17: 410666 | AF17: =AE17/AE$20 -> 0.0062257026 | AG17: 880000 | AH17: =AG17/AG$20 -> 0.011449105 | AI17: =SUM(AC17+AE17+AG17) -> 1290666 | AJ17: =SUM(AA17,S17,K17,AI17) -> 1290666 | AK17: =AJ17-#REF! -> #REF!
G18: 일반세탁물(강서바른) | K18: =SUM(H18:J18) -> 0 | N18: =M18/$M$20 -> 0 | P18: =O18/$O$20 -> 0 | R18: =Q18/$Q$20 -> 0 | S18: =M18+O18+Q18 -> 0 | T18: =S18/$S$20 -> 0 | V18: =U18/$U$20 -> 0 | X18: =W18/W$20 -> 0 | Y18: 0 | Z18: =Y18/Y$20 -> 0 | AA18: =SUM(U18+W18+Y18) -> 0 | AB18: =AA18/AA$20 -> 0 | AC18: 0 | AD18: =AC18/AC$20 -> 0 | AE18: 814545 | AF18: =AE18/AE$20 -> 0.012348514 | AG18: 1745454.4 | AH18: =AG18/AG$20 -> 0.022708968 | AI18: =SUM(AC18+AE18+AG18) -> 2559999.4 | AJ18: =SUM(AA18,S18,K18,AI18) -> 2559999.4 | AK18: =AJ18-#REF! -> #REF!
G19: 메디탁 매출 합계 | M19: =SUM(M16) -> 0 | N19: =M19/M$20 -> 0 | O19: =SUM(O16) -> 0 | P19: =O19/O$20 -> 0 | Q19: =SUM(Q16) -> 0 | R19: =Q19/Q$20 -> 0 | U19: =SUM(U16) -> 0 | V19: =U19/U$20 -> 0 | W19: =SUM(W16) -> 0 | X19: =W19/W$20 -> 0 | Y19: =SUM(Y16) -> 1500000 | Z19: =Y19/Y$20 -> 0.020330432 | AA19: =SUM(U19+W19+Y19) -> 1500000 | AC19: =SUM(AC16:AC18) -> 1500000 | AD19: =AC19/AC$20 -> 0.023689515 | AE19: =SUM(AE16:AE18) -> 2725211 | AF19: =AE19/AE$20 -> 0.041314239 | AG19: =SUM(AG16:AG18) -> 4125454.4 | AH19: =AG19/AG$20 -> 0.053673594 | AI19: =SUM(AI16:AI18) -> 8350665.4 | AJ19: =SUM(AA19,S19,K19,AI19) -> 9850665.4 | AK19: =AJ19-#REF! -> #REF!
B20: 스테리케어 매출 합계액 (부가세 별도가 기준) | H20: =H10+H15 -> 56794258 | I20: =I10+I15 -> 54505759 | J20: =J10+J15 -> 56838983 | K20: =K10+K15 -> 1.68139e+08 | L20: =K20/$K$20 -> 1 | M20: =M10+M15 -> 64344695 | N20: =M20/$M$20 -> 1 | O20: =O10+O15 -> 56863108 | P20: =O20/$O$20 -> 1 | Q20: =Q10+Q15 -> 64721609 | R20: =Q20/$Q$20 -> 1 | S20: =S10+S15 -> 185929412 | T20: =S20/$S$20 -> 1 | U20: =U10+U15 -> 73886329 | V20: =U20/$U$20 -> 1 | W20: =W10+W15 -> 66273503 | X20: =W20/W$20 -> 1 | Y20: =Y10+Y15+Y19 -> 73781021 | Z20: =Y20/Y$20 -> 1 | AA20: =SUM(U20+W20+Y20) -> 213940853 | AB20: =AA20/AA$20 -> 1 | AC20: =AC10+AC15+AC19 -> 63319152 | AD20: =AC20/AC$20 -> 1 | AE20: =AE10+AE15+AE19 -> 65962997 | AF20: =AE20/AE$20 -> 1 | AG20: =AG10+AG15+AG19 -> 76861900 | AH20: =AG20/AG$20 -> 1 | AI20: =SUM(AC20+AE20+AG20) -> 2.0614405e+08 | AJ20: =SUM(AA20,S20,K20,AI20) -> 7.7415331e+08 | AK20: =AJ20-#REF! -> #REF!
B21: 3 | G21: 직접 노무비 (1) | H21: =#REF! -> #REF! | I21: =#REF! -> #REF! | J21: =#REF! -> #REF! | K21: =SUM(H21:J21) -> #REF! | L21: =K21/$K$20 -> #REF! | M21: =#REF! -> #REF! | N21: =M21/$M$20 -> #REF! | O21: =#REF! -> #REF! | P21: =O21/O$20 -> #REF! | Q21: =#REF! -> #REF! | R21: =Q21/Q$20 -> #REF! | S21: =M21+O21+Q21 -> #REF! | T21: =S21/$S$20 -> #REF! | U21: =#REF! -> #REF! | V21: =U21/U$20 -> #REF! | W21: =#REF! -> #REF! | X21: =W21/W$20 -> #REF! | Y21: =#REF! -> #REF! | Z21: =Y21/Y$20 -> #REF! | AA21: =SUM(U21+W21+Y21) -> #REF! | AB21: =AA21/AA$20 -> #REF! | AC21: =#REF! -> #REF! | AD21: =AC21/AC$20 -> #REF! | AE21: =#REF! -> #REF! | AF21: =AE21/AE$20 -> #REF! | AG21: =#REF! -> #REF! | AH21: =AG21/AG$20 -> #REF! | AI21: =SUM(AC21+AE21+AG21) -> #REF! | AJ21: =SUM(AA21,S21,K21,AI21) -> #REF! | AK21: =AJ21-#REF! -> #REF!
B22: 4 | G22: 총 노무비 합계 (1)+(2) | H22: =#REF! -> #REF! | I22: =#REF! -> #REF! | J22: =#REF! -> #REF! | K22: =SUM(H22:J22) -> #REF! | L22: =K22/$K$20 -> #REF! | M22: =#REF! -> #REF! | N22: =M22/$M$20 -> #REF! | O22: =#REF! -> #REF! | P22: =O22/O$20 -> #REF! | Q22: =#REF! -> #REF! | R22: =Q22/Q$20 -> #REF! | S22: =M22+O22+Q22 -> #REF! | T22: =S22/$S$20 -> #REF! | U22: =#REF! -> #REF! | V22: =U22/U$20 -> #REF! | W22: =#REF! -> #REF! | X22: =W22/W$20 -> #REF! | Y22: =#REF! -> #REF! | Z22: =Y22/Y$20 -> #REF! | AA22: =SUM(U22+W22+Y22) -> #REF! | AB22: =AA22/AA$20 -> #REF! | AC22: =#REF! -> #REF! | AD22: =AC22/AC$20 -> #REF! | AE22: =#REF! -> #REF! | AF22: =AE22/AE$20 -> #REF! | AG22: =#REF! -> #REF! | AH22: =AG22/AG$20 -> #REF! | AI22: =SUM(AC22+AE22+AG22) -> #REF! | AJ22: =SUM(AA22,S22,K22,AI22) -> #REF! | AK22: =AJ22-#REF! -> #REF!
B23: 5 | G23: 연장수당 | H23: 3624174 | I23: 1653330 | J23: 2240381 | K23: =SUM(H23:J23) -> 7517885 | L23: =K23/$K$20 -> 0.044712321 | M23: 1886578 | N23: =M23/$M$20 -> 0.029319869 | O23: 3014728 | P23: =O23/O$20 -> 0.053017292 | Q23: 1864888 | R23: =Q23/Q$20 -> 0.028813993 | S23: =M23+O23+Q23 -> 6766194 | T23: =S23/$S$20 -> 0.036391198 | U23: 1645808 | V23: =U23/U$20 -> 0.022274865 | W23: 2129226 | X23: =W23/W$20 -> 0.032127863 | Y23: 2461458 | Z23: =Y23/Y$20 -> 0.033361669 | AA23: =SUM(U23+W23+Y23) -> 6236492 | AB23: =AA23/AA$20 -> 0.029150543 | AC23: 491882 | AD23: =AC23/AC$20 -> 0.0077682973 | AE23: 1624458.4 | AF23: =AE23/AE$20 -> 0.024626812 | AG23: 1136417 | AH23: =AG23/AG$20 -> 0.01478518 | AI23: =SUM(AC23+AE23+AG23) -> 3252757.4 | AJ23: =SUM(AA23,S23,K23,AI23) -> 23773328 | AL23: 연장수당+야간수당+박우생 기타수당 100만원포함
B24: 6 | G24: 전기요금(한국전력공사) | H24: 3795954 | I24: 4162788 | J24: 4165314 | K24: =SUM(H24:J24) -> 12124056 | L24: =K24/$K$20 -> 0.07210734 | M24: 4174230 | N24: =M24/$M$20 -> 0.064872947 | O24: =#REF! -> #REF! | P24: =O24/O$20 -> #REF! | Q24: =#REF! -> #REF! | R24: =Q24/Q$20 -> #REF! | S24: =M24+O24+Q24 -> #REF! | T24: =S24/$S$20 -> #REF! | U24: =#REF! -> #REF! | V24: =U24/U$20 -> #REF! | W24: =#REF! -> #REF! | X24: =W24/W$20 -> #REF! | Y24: =#REF! -> #REF! | Z24: =Y24/Y$20 -> #REF! | AA24: =SUM(U24+W24+Y24) -> #REF! | AB24: =AA24/AA$20 -> #REF! | AC24: =#REF! -> #REF! | AD24: =AC24/AC$20 -> #REF! | AE24: =#REF! -> #REF! | AF24: =AE24/AE$20 -> #REF! | AG24: =#REF! -> #REF! | AH24: =AG24/AG$20 -> #REF! | AI24: =SUM(AC24+AE24+AG24) -> #REF! | AJ24: =SUM(AA24,S24,K24,AI24) -> #REF! | AK24: =AJ24-#REF! -> #REF! | AL24: 청구요금-부가세대급금 (전력기금 포함)
B25: 7 | G25: 가스요금(해동에너지) | H25: 8355215 | I25: 8188170 | J25: 7242856 | K25: =SUM(H25:J25) -> 23786241 | L25: =K25/$K$20 -> 0.14146772 | M25: 6434092 | N25: =M25/$M$20 -> 0.099994133 | O25: =#REF! -> #REF! | P25: =O25/O$20 -> #REF! | Q25: =#REF! -> #REF! | R25: =Q25/Q$20 -> #REF! | S25: =M25+O25+Q25 -> #REF! | T25: =S25/$S$20 -> #REF! | U25: =#REF! -> #REF! | V25: =U25/U$20 -> #REF! | W25: =#REF! -> #REF! | X25: =W25/W$20 -> #REF! | Y25: =#REF! -> #REF! | Z25: =Y25/Y$20 -> #REF! | AA25: =SUM(U25+W25+Y25) -> #REF! | AB25: =AA25/AA$20 -> #REF! | AC25: =#REF! -> #REF! | AD25: =AC25/AC$20 -> #REF! | AE25: =#REF! -> #REF! | AF25: =AE25/AE$20 -> #REF! | AG25: =#REF! -> #REF! | AH25: =AG25/AG$20 -> #REF! | AI25: =SUM(AC25+AE25+AG25) -> #REF! | AJ25: =SUM(AA25,S25,K25,AI25) -> #REF! | AK25: =AJ25-#REF! -> #REF! | AL25: 해동에너지

Sheet 26년 3월(결산용)
C1: ◎ 스테리케어 손익 결산 (부가세별도가 기준)
H2: 2026년 (귀속월 기준)
C3: 대분류 | D3: 중분류 | E3: 소분류 | F3: 상대거래처 | G3: 상세내역 | H3: 1월 | I3: 1월 비율계상 (%) | J3: 2월 | K3: 2월 비율계상 (%) | L3: 3월 | M3: 3월 비율계상 (%) | N3: 1분기 합계 | O3: 1분기 비율계상 (%) | P3: 4월 | Q3: 4월 비율계상 (%) | R3: 5월 | S3: 5월 비율계상 (%) | T3: 6월 | U3: 6월 비율계상 (%) | V3: 2분기 합계 | W3: 2분기 비율계상 (%) | X3: 7월 | Y3: 7월 비율계상 (%) | Z3: 8월 | AA3: 8월 비율계상 (%) | AB3: 9월 | AC3: 9월 비율계상 (%) | AD3: 3분기 합계 | AE3: 3분기 비율계상 (%) | AF3: 10월 | AG3: 10월 비율계상 (%) | AH3: 11월 | AI3: 11월 비율계상 (%) | AJ3: 12월 | AK3: 12월 비율계상 (%) | AL3: 4분기 합계 | AM3: 4분기 비율계상 (%) | AN3: 2026년 합계 | AO3: 비고
C4: 매출원가 | D4: 서비스 매출원가 | E4: 가운원가 | F4: 부천세종병원 | G4: 가운원가반영 | H4: ='월별원가(류)5월'!Q11 -> 1298904.5 | I4: =H4/H11 -> 0.040444379 | J4: ='월별원가(류)5월'!R11 -> 1029270.9 | K4: =J4/J11 -> 0.03687823 | L4: ='월별원가(류)5월'!S11 -> 1021823.6 | M4: =L4/L11 -> 0.03310279 | N4: =SUM(H4,J4,L4) -> 3349999.1 | O4: =N4/N11 -> 0.036856102 | Q4: =P4/P11 -> #DIV/0! | S4: =R4/R11 -> #DIV/0! | U4: =T4/T11 -> #DIV/0! | V4: =SUM(P4,R4,T4) -> 0 | W4: =V4/V$27 -> #DIV/0! | Y4: =X4/X11 -> #DIV/0! | AA4: =Z4/Z11 -> #DIV/0! | AC4: =AB4/AB11 -> #DIV/0! | AD4: =SUM(X4,Z4,AB4) -> 0 | AE4: =AD4/AD$27 -> #DIV/0! | AG4: =AF4/AF11 -> #DIV/0! | AI4: =AH4/AH11 -> #DIV/0! | AK4: =AJ4/AJ11 -> #DIV/0! | AL4: =SUM(AF4,AH4,AJ4) -> 0 | AM4: =AL4/AL$27 -> #DIV/0! | AN4: =SUM(AD4,V4,N4,AL4) -> 3349999.1
F5: 인천세종병원 | G5: 가운원가반영 | H5: ='월별원가(류)5월'!Q19 -> 1631721.8 | I5: =H5/H16 -> 0.044456817 | J5: ='월별원가(류)5월'!R19 -> 1289300.9 | K5: =J5/J16 -> 0.041560373 | L5: ='월별원가(류)5월'!S19 -> 1459183.6 | M5: =L5/L16 -> 0.040488366 | N5: =SUM(H5,J5,L5) -> 4380206.4 | O5: =N5/N16 -> 0.042212566 | Q5: =P5/P16 -> #DIV/0! | S5: =R5/R16 -> #DIV/0! | U5: =T5/T16 -> #DIV/0! | V5: =SUM(P5,R5,T5) -> 0 | W5: =V5/V$27 -> #DIV/0! | Y5: =X5/X16 -> #DIV/0! | AA5: =Z5/Z16 -> #DIV/0! | AC5: =AB5/AB16 -> #DIV/0! | AD5: =SUM(X5,Z5,AB5) -> 0 | AE5: =AD5/AD$27 -> #DIV/0! | AG5: =AF5/AF16 -> #DIV/0! | AI5: =AH5/AH16 -> #DIV/0! | AK5: =AJ5/AJ16 -> #DIV/0! | AL5: =SUM(AF5,AH5,AJ5) -> 0 | AM5: =AL5/AL$27 -> #DIV/0! | AN5: =SUM(AD5,V5,N5,AL5) -> 4380206.4
B6: 가운 원가 합계 | H6: =SUM(H4:H5) -> 2930626.4 | I6: =H6/H27 -> 0.034547478 | J6: =SUM(J4:J5) -> 2318571.8 | K6: =J6/J27 -> 0.031432881 | L6: =SUM(L4:L5) -> 2481007.3 | M6: =L6/L27 -> 0.024404956 | N6: =SUM(H6,J6,L6) -> 7730205.5 | O6: =N6/N27 -> 0.029702821 | P6: =SUM(P4:P5) -> 0 | Q6: =P6/P27 -> #DIV/0! | R6: =SUM(R4:R5) -> 0 | S6: =R6/R27 -> #DIV/0! | T6: =SUM(T4:T5) -> 0 | U6: =T6/T27 -> #DIV/0! | V6: =SUM(P6,R6,T6) -> 0 | W6: =V6/V$27 -> #DIV/0! | X6: =SUM(X4:X5) -> 0 | Y6: =X6/X27 -> #DIV/0! | Z6: =SUM(Z4:Z5) -> 0 | AA6: =Z6/Z27 -> #DIV/0! | AB6: =SUM(AB4:AB5) -> 0 | AC6: =AB6/AB27 -> #DIV/0! | AD6: =SUM(X6,Z6,AB6) -> 0 | AE6: =AD6/AD$27 -> #DIV/0! | AF6: =SUM(AF4:AF5) -> 0 | AG6: =AF6/AF27 -> #DIV/0! | AH6: =SUM(AH4:AH5) -> 0 | AI6: =AH6/AH27 -> #DIV/0! | AJ6: =SUM(AJ4:AJ5) -> 0 | AK6: =AJ6/AJ27 -> #DIV/0! | AL6: =SUM(AF6,AH6,AJ6) -> 0 | AM6: =AL6/AL$27 -> #DIV/0! | AN6: =SUM(AN4:AN5) -> 7730205.5
C7: 매출 | D7: 서비스매출 | E7: 서비스매출 | F7: 부천세종병원 | G7: 일반세탁물 | H7: 26032869 | I7: =H7/H$27 -> 0.3068866 | J7: 23030641 | K7: =J7/J$27 -> 0.31222643 | L7: 25936284 | M7: =L7/L$27 -> 0.25512778 | N7: =SUM(H7,J7,L7) -> 74999794 | O7: =N7/$N$27 -> 0.28818193 | Q7: =P7/$P$27 -> #DIV/0! | S7: =R7/$R$27 -> #DIV/0! | U7: =T7/$T$27 -> #DIV/0! | V7: =SUM(P7,R7,T7) -> 0 | W7: =V7/V$27 -> #DIV/0! | Y7: =X7/X$27 -> #DIV/0! | AA7: =Z7/Z$27 -> #DIV/0! | AC7: =AB7/AB$27 -> #DIV/0! | AD7: =SUM(X7,Z7,AB7) -> 0 | AE7: =AD7/AD$27 -> #DIV/0! | AG7: =AF7/AF$27 -> #DIV/0! | AI7: =AH7/AH$27 -> #DIV/0! | AK7: =AJ7/AJ$27 -> #DIV/0! | AL7: =SUM(AF7,AH7,AJ7) -> 0 | AM7: =AL7/AL$27 -> #DIV/0! | AN7: =SUM(N7+V7+AD7+AL7) -> 74999794
G8: 렌탈가운_멸균 | H8: 4792500 | I8: =H8/H$27 -> 0.056496041 | J8: 3709800 | K8: =J8/J$27 -> 0.050293764 | L8: 3612600 | M8: =L8/L$27 -> 0.035536109 | N8: =SUM(H8,J8,L8) -> 12114900 | O8: =N8/$N$27 -> 0.046550731 | Q8: =P8/$P$27 -> #DIV/0! | S8: =R8/$R$27 -> #DIV/0! | U8: =T8/$T$27 -> #DIV/0! | V8: =SUM(P8,R8,T8) -> 0 | W8: =V8/V$27 -> #DIV/0! | Y8: =X8/X$27 -> #DIV/0! | AA8: =Z8/Z$27 -> #DIV/0! | AC8: =AB8/AB$27 -> #DIV/0! | AD8: =SUM(X8,Z8,AB8) -> 0 | AE8: =AD8/AD$27 -> #DIV/0! | AG8: =AF8/AF$27 -> #DIV/0! | AI8: =AH8/AH$27 -> #DIV/0! | AK8: =AJ8/AJ$27 -> #DIV/0! | AL8: =SUM(AF8,AH8,AJ8) -> 0 | AM8: =AL8/AL$27 -> #DIV/0! | AN8: =SUM(N8+V8+AD8+AL8) -> 12114900
G9: 렌탈가운_비멸균 | H9: 271364 | I9: =H9/H$27 -> 0.003198955 | J9: 271364 | K9: =J9/J$27 -> 0.0036788821 | L9: 282955 | M9: =L9/L$27 -> 0.0027833471 | N9: =SUM(H9,J9,L9) -> 825683 | O9: =N9/$N$27 -> 0.0031726343 | Q9: =P9/$P$27 -> #DIV/0! | S9: =R9/$R$27 -> #DIV/0! | U9: =T9/$T$27 -> #DIV/0! | V9: =SUM(P9,R9,T9) -> 0 | W9: =V9/V$27 -> #DIV/0! | Y9: =X9/X$27 -> #DIV/0! | AA9: =Z9/Z$27 -> #DIV/0! | AC9: =AB9/AB$27 -> #DIV/0! | AD9: =SUM(X9,Z9,AB9) -> 0 | AE9: =AD9/AD$27 -> #DIV/0! | AG9: =AF9/AF$27 -> #DIV/0! | AI9: =AH9/AH$27 -> #DIV/0! | AK9: =AJ9/AJ$27 -> #DIV/0! | AL9: =SUM(AF9,AH9,AJ9) -> 0 | AM9: =AL9/AL$27 -> #DIV/0! | AN9: =SUM(N9+V9+AD9+AL9) -> 825683
G10: 렌탈 멸균 프로텍트커버 | H10: 1019091 | I10: =H10/H$27 -> 0.012013481 | J10: 898182 | K10: =J10/J$27 -> 0.012176655 | L10: 1036364 | M10: =L10/L$27 -> 0.010194415 | N10: =SUM(H10,J10,L10) -> 2953637 | O10: =N10/$N$27 -> 0.011349162 | Q10: =P10/$P$27 -> #DIV/0! | S10: =R10/$R$27 -> #DIV/0! | U10: =T10/$T$27 -> #DIV/0! | V10: =SUM(P10,R10,T10) -> 0 | W10: =V10/V$27 -> #DIV/0! | Y10: =X10/X$27 -> #DIV/0! | AA10: =Z10/Z$27 -> #DIV/0! | AC10: =AB10/AB$27 -> #DIV/0! | AD10: =SUM(X10,Z10,AB10) -> 0 | AE10: =AD10/AD$27 -> #DIV/0! | AG10: =AF10/AF$27 -> #DIV/0! | AI10: =AH10/AH$27 -> #DIV/0! | AK10: =AJ10/AJ$27 -> #DIV/0! | AL10: =SUM(AF10,AH10,AJ10) -> 0 | AM10: =AL10/AL$27 -> #DIV/0! | AN10: =SUM(N10+V10+AD10+AL10) -> 2953637
G11: 부천세종병원 매출 합계 | H11: =SUM(H7:H10) -> 32115824 | I11: =H11/H$27 -> 0.37859508 | J11: =SUM(J7:J10) -> 27909987 | K11: =J11/J$27 -> 0.37837573 | L11: =SUM(L7:L10) -> 30868203 | M11: =L11/L$27 -> 0.30364165 | N11: =SUM(H11,J11,L11) -> 90894014 | O11: =N11/$N$27 -> 0.34925445 | P11: =SUM(P7:P10) -> 0 | Q11: =P11/P27 -> #DIV/0! | R11: =SUM(R7:R10) -> 0 | S11: =R11/R27 -> #DIV/0! | T11: =SUM(T7:T10) -> 0 | U11: =T11/T27 -> #DIV/0! | V11: =SUM(P11,R11,T11) -> 0 | W11: =V11/V$27 -> #DIV/0! | X11: =SUM(X7:X10) -> 0 | Y11: =X11/X27 -> #DIV/0! | Z11: =SUM(Z7:Z10) -> 0 | AA11: =Z11/Z27 -> #DIV/0! | AB11: =SUM(AB7:AB10) -> 0 | AC11: =AB11/AB27 -> #DIV/0! | AD11: =SUM(X11,Z11,AB11) -> 0 | AE11: =AD11/AD$27 -> #DIV/0! | AF11: =SUM(AF7:AF10) -> 0 | AG11: =AF11/AF27 -> #DIV/0! | AH11: =SUM(AH7:AH10) -> 0 | AI11: =AH11/AH27 -> #DIV/0! | AJ11: =SUM(AJ7:AJ10) -> 0 | AK11: =AJ11/AJ27 -> #DIV/0! | AL11: =SUM(AF11,AH11,AJ11) -> 0 | AM11: =AL11/AL$27 -> #DIV/0! | AN11: =SUM(AN7:AN10) -> 90894014
F12: 인천세종병원 | G12: 일반세탁물 | H12: 29669531 | I12: =H12/H$27 -> 0.34975713 | J12: 25419534 | K12: =J12/J$27 -> 0.34461266 | L12: 29658333 | M12: =L12/L$27 -> 0.2917405 | N12: =SUM(H12,J12,L12) -> 84747398 | O12: =N12/$N$27 -> 0.32563647 | Q12: =P12/$P$27 -> #DIV/0! | S12: =R12/$R$27 -> #DIV/0! | U12: =T12/$T$27 -> #DIV/0! | V12: =SUM(P12,R12,T12) -> 0 | W12: =V12/V$27 -> #DIV/0! | Y12: =X12/X$27 -> #DIV/0! | AA12: =Z12/Z$27 -> #DIV/0! | AC12: =AB12/AB$27 -> #DIV/0! | AD12: =SUM(X12,Z12,AB12) -> 0 | AE12: =AD12/AD$27 -> #DIV/0! | AG12: =AF12/AF$27 -> #DIV/0! | AI12: =AH12/AH$27 -> #DIV/0! | AK12: =AJ12/AJ$27 -> #DIV/0! | AL12: =SUM(AF12,AH12,AJ12) -> 0 | AM12: =AL12/AL$27 -> #DIV/0! | AN12: =SUM(AD12,V12,N12,AL12) -> 84747398
G13: 렌탈가운_멸균 | H13: 6107400 | I13: =H13/H$27 -> 0.071996645 | J13: 4760100 | K13: =J13/J$27 -> 0.064532682 | L13: 5524200 | M13: =L13/L$27 -> 0.054339969 | N13: =SUM(H13,J13,L13) -> 16391700 | O13: =N13/$N$27 -> 0.062984062 | Q13: =P13/$P$27 -> #DIV/0! | S13: =R13/$R$27 -> #DIV/0! | U13: =T13/$T$27 -> #DIV/0! | V13: =SUM(P13,R13,T13) -> 0 | W13: =V13/V$27 -> #DIV/0! | Y13: =X13/X$27 -> #DIV/0! | AA13: =Z13/Z$27 -> #DIV/0! | AC13: =AB13/AB$27 -> #DIV/0! | AD13: =SUM(X13,Z13,AB13) -> 0 | AE13: =AD13/AD$27 -> #DIV/0! | AG13: =AF13/AF$27 -> #DIV/0! | AI13: =AH13/AH$27 -> #DIV/0! | AK13: =AJ13/AJ$27 -> #DIV/0! | AL13: =SUM(AF13,AH13,AJ13) -> 0 | AM13: =AL13/AL$27 -> #DIV/0! | AN13: =SUM(N13+V13+AD13+AL13) -> 16391700
G14: 렌탈가운_비멸균 | H14: 926592 | I14: =H14/H$27 -> 0.010923063 | J14: 842727 | K14: =J14/J$27 -> 0.011424851 | L14: 857045 | M14: =L14/L$27 -> 0.0084305055 | N14: =SUM(H14,J14,L14) -> 2626364 | O14: =N14/$N$27 -> 0.010091636 | Q14: =P14/$P$27 -> #DIV/0! | S14: =R14/$R$27 -> #DIV/0! | U14: =T14/$T$27 -> #DIV/0! | V14: =SUM(P14,R14,T14) -> 0 | W14: =V14/V$27 -> #DIV/0! | Y14: =X14/X$27 -> #DIV/0! | AA14: =Z14/Z$27 -> #DIV/0! | AC14: =AB14/AB$27 -> #DIV/0! | AD14: =SUM(X14,Z14,AB14) -> 0 | AE14: =AD14/AD$27 -> #DIV/0! | AG14: =AF14/AF$27 -> #DIV/0! | AI14: =AH14/AH$27 -> #DIV/0! | AK14: =AJ14/AJ$27 -> #DIV/0! | AL14: =SUM(AF14,AH14,AJ14) -> 0 | AM14: =AL14/AL$27 -> #DIV/0! | AN14: =SUM(N14+V14+AD14+AL14) -> 2626364
G15: 렌탈 멸균 프로텍트커버 | H15: 0 | I15: =H15/H$27 -> 0 | J15: 0 | K15: =J15/J$27 -> 0 | L15: 0 | M15: =L15/L$27 -> 0 | N15: =SUM(H15,J15,L15) -> 0 | O15: =N15/$N$27 -> 0 | Q15: =P15/$P$27 -> #DIV/0! | S15: =R15/$R$27 -> #DIV/0! | U15: =T15/$T$27 -> #DIV/0! | V15: =SUM(P15,R15,T15) -> 0 | W15: =V15/V$27 -> #DIV/0! | Y15: =X15/X$27 -> #DIV/0! | AA15: =Z15/Z$27 -> #DIV/0! | AC15: =AB15/AB$27 -> #DIV/0! | AD15: =SUM(X15,Z15,AB15) -> 0 | AE15: =AD15/AD$27 -> #DIV/0! | AG15: =AF15/AF$27 -> #DIV/0! | AI15: =AH15/AH$27 -> #DIV/0! | AK15: =AJ15/AJ$27 -> #DIV/0! | AL15: =SUM(AF15,AH15,AJ15) -> 0 | AM15: =AL15/AL$27 -> #DIV/0! | AN15: =SUM(N15+V15+AD15+AL15) -> 0
G16: 인천세종병원 매출 합계 | H16: =SUM(H12:H15) -> 36703523 | I16: =H16/H$27 -> 0.43267684 | J16: =SUM(J12:J15) -> 31022361 | K16: =J16/J$27 -> 0.42057019 | L16: =SUM(L12:L15) -> 36039578 | M16: =L16/L$27 -> 0.35451098 | N16: =SUM(H16,J16,L16) -> 103765462 | O16: =N16/$N$27 -> 0.39871217 | P16: =SUM(P12:P15) -> 0 | Q16: =P16/$P$27 -> #DIV/0! | R16: =SUM(R12:R15) -> 0 | S16: =R16/$R$27 -> #DIV/0! | T16: =SUM(T12:T15) -> 0 | U16: =T16/$T$27 -> #DIV/0! | V16: =SUM(P16,R16,T16) -> 0 | W16: =V16/V$27 -> #DIV/0! | X16: =SUM(X12:X15) -> 0 | Y16: =X16/X27 -> #DIV/0! | Z16: =SUM(Z12:Z15) -> 0 | AA16: =Z16/Z27 -> #DIV/0! | AB16: =SUM(AB12:AB15) -> 0 | AC16: =AB16/AB27 -> #DIV/0! | AD16: =SUM(X16,Z16,AB16) -> 0 | AE16: =AD16/AD$27 -> #DIV/0! | AF16: =SUM(AF12:AF15) -> 0 | AG16: =AF16/AF27 -> #DIV/0! | AH16: =SUM(AH12:AH15) -> 0 | AI16: =AH16/AH27 -> #DIV/0! | AJ16: =SUM(AJ12:AJ15) -> 0 | AK16: =AJ16/AJ27 -> #DIV/0! | AL16: =SUM(AF16,AH16,AJ16) -> 0 | AM16: =AL16/AL$27 -> #DIV/0! | AN16: =SUM(AN12:AN15) -> 103765462
F17: 메디탁 | G17: 일반세탁물(허균) | H17: 1500000 | I17: =H17/H$27 -> 0.017682642 | J17: 1500000 | K17: =J17/J$27 -> 0.020335502 | L17: 0 | M17: =L17/L$27 -> 0 | N17: =SUM(H17,J17,L17) -> 3000000 | O17: =N17/N$27 -> 0.011527309 | P17: 0 | Q17: =P17/P$27 -> #DIV/0! | R17: 0 | S17: =R17/R$27 -> #DIV/0! | T17: 0 | U17: =T17/T$27 -> #DIV/0! | V17: =SUM(P17,R17,T17) -> 0 | W17: =V17/V$27 -> #DIV/0! | X17: 0 | Y17: =X17/X$27 -> #DIV/0! | Z17: 0 | AA17: =Z17/Z$27 -> #DIV/0! | AB17: 0 | AC17: =AB17/AB$27 -> #DIV/0! | AD17: =SUM(X17,Z17,AB17) -> 0 | AE17: =AD17/AD$27 -> #DIV/0! | AF17: 0 | AG17: =AF17/AF$27 -> #DIV/0! | AH17: 0 | AI17: =AH17/AH$27 -> #DIV/0! | AJ17: 0 | AK17: =AJ17/AJ$27 -> #DIV/0! | AL17: =SUM(AF17,AH17,AJ17) -> 0 | AM17: =AL17/AL$27 -> #DIV/0! | AN17: =SUM(N17+V17+AD17+AL17) -> 3000000
G18: 일반세탁물(나움) | H18: 880000 | I18: =H18/H$27 -> 0.010373817 | J18: 880000 | K18: =J18/J$27 -> 0.011930161 | L18: 0 | M18: =L18/L$27 -> 0 | N18: =SUM(H18,J18,L18) -> 1760000 | O18: =N18/N$27 -> 0.0067626878 | P18: 0 | Q18: =P18/P$27 -> #DIV/0! | R18: 0 | S18: =R18/R$27 -> #DIV/0! | T18: 0 | U18: =T18/T$27 -> #DIV/0! | V18: =SUM(P18,R18,T18) -> 0 | W18: =V18/V$27 -> #DIV/0! | X18: 0 | Y18: =X18/X$27 -> #DIV/0! | Z18: 0 | AA18: =Z18/Z$27 -> #DIV/0! | AB18: 0 | AC18: =AB18/AB$27 -> #DIV/0! | AD18: =SUM(X18,Z18,AB18) -> 0 | AE18: =AD18/AD$27 -> #DIV/0! | AF18: 0 | AG18: =AF18/AF$27 -> #DIV/0! | AH18: 0 | AI18: =AH18/AH$27 -> #DIV/0! | AJ18: 0 | AK18: =AJ18/AJ$27 -> #DIV/0! | AL18: =SUM(AF18,AH18,AJ18) -> 0 | AM18: =AL18/AL$27 -> #DIV/0! | AN18: =SUM(N18+V18+AD18+AL18) -> 1760000
G19: 일반세탁물(강서바른) | H19: 1745455 | I19: =H19/H$27 -> 0.02057617 | J19: 1745454.4 | K19: =J19/J$27 -> 0.023663128 | L19: 0 | M19: =L19/L$27 -> 0 | N19: =SUM(H19,J19,L19) -> 3490909.4 | O19: =N19/N$27 -> 0.013413597 | P19: 0 | Q19: =P19/P$27 -> #DIV/0! | R19: 0 | S19: =R19/R$27 -> #DIV/0! | T19: 0 | U19: =T19/T$27 -> #DIV/0! | V19: =SUM(P19,R19,T19) -> 0 | W19: =V19/V$27 -> #DIV/0! | X19: 0 | Y19: =X19/X$27 -> #DIV/0! | Z19: 0 | AA19: =Z19/Z$27 -> #DIV/0! | AB19: 0 | AC19: =AB19/AB$27 -> #DIV/0! | AD19: =SUM(X19,Z19,AB19) -> 0 | AE19: =AD19/AD$27 -> #DIV/0! | AF19: 0 | AG19: =AF19/AF$27 -> #DIV/0! | AH19: 0 | AI19: =AH19/AH$27 -> #DIV/0! | AJ19: 0 | AK19: =AJ19/AJ$27 -> #DIV/0! | AL19: =SUM(AF19,AH19,AJ19) -> 0 | AM19: =AL19/AL$27 -> #DIV/0! | AN19: =SUM(N19+V19+AD19+AL19) -> 3490909.4
G20: 메디탁 매출 합계 | H20: =SUM(H17:H19) -> 4125455 | I20: =H20/H$27 -> 0.048632629 | J20: =SUM(J17:J19) -> 4125454.4 | K20: =J20/J$27 -> 0.055928791 | L20: =SUM(L17:L19) -> 0 | M20: =L20/L$27 -> 0 | N20: =SUM(H20,J20,L20) -> 8250909.4 | O20: =N20/N$27 -> 0.031703593 | P20: =SUM(P17:P19) -> 0 | Q20: =P$20/P$27 -> #DIV/0! | R20: =SUM(R17:R19) -> 0 | S20: =R$20/R$27 -> #DIV/0! | T20: =SUM(T17:T19) -> 0 | U20: =T$20/T$27 -> #DIV/0! | V20: =SUM(P20,R20,T20) -> 0 | X20: =SUM(X17:X19) -> 0 | Y20: =X$20/X$27 -> #DIV/0! | Z20: =SUM(Z17:Z19) -> 0 | AA20: =Z$20/Z$27 -> #DIV/0! | AB20: =SUM(AB17:AB19) -> 0 | AC20: =AB$20/AB$27 -> #DIV/0! | AD20: =SUM(X20,Z20,AB20) -> 0 | AF20: =SUM(AF17:AF19) -> 0 | AG20: =AF$20/AF$27 -> #DIV/0! | AH20: =SUM(AH17:AH19) -> 0 | AI20: =AH$20/AH$27 -> #DIV/0! | AJ20: =SUM(AJ17:AJ19) -> 0 | AK20: =AJ$20/AJ$27 -> #DIV/0! | AL20: =SUM(AF20,AH20,AJ20) -> 0 | AN20: =SUM(AN17:AN19) -> 8250909.4
F21: 파주병원 | G21: 일반세탁물 | H21: 11884151 | I21: =H21/H$27 -> 0.14009546 | J21: 10213913 | K21: =J21/J$27 -> 0.13847003 | L21: 11649696 | M21: =L21/L$27 -> 0.11459471 | N21: =SUM(H21,J21,L21) -> 33747760 | O21: =N21/N$27 -> 0.12967362 | Q21: =P21/P$27 -> #DIV/0! | S21: =R21/R$27 -> #DIV/0! | U21: =T21/T$27 -> #DIV/0! | V21: =SUM(P21,R21,T21) -> 0 | W21: =V21/V$27 -> #DIV/0! | Y21: =X21/X$27 -> #DIV/0! | AA21: =Z21/Z$27 -> #DIV/0! | AC21: =AB21/AB$27 -> #DIV/0! | AD21: =SUM(X21,Z21,AB21) -> 0 | AE21: =AD21/AD$27 -> #DIV/0! | AG21: =AF21/AF$27 -> #DIV/0! | AI21: =AH21/AH$27 -> #DIV/0! | AK21: =AJ21/AJ$27 -> #DIV/0! | AL21: =SUM(AF21,AH21,AJ21) -> 0 | AM21: =AL21/AL$27 -> #DIV/0! | AN21: =SUM(N21+V21+AD21+AL21) -> 33747760
G22: 파주병원 매출 합계 | H22: =SUM(H21) -> 11884151 | I22: =H22/H$27 -> 0.14009546 | J22: =SUM(J21) -> 10213913 | K22: =J22/J$27 -> 0.13847003 | L22: =SUM(L21) -> 11649696 | M22: =L22/L$27 -> 0.11459471 | N22: =SUM(H22,J22,L22) -> 33747760 | O22: =N22/N$27 -> 0.12967362 | P22: =SUM(P21) -> 0 | Q22: =P$20/P$27 -> #DIV/0! | R22: =SUM(R21) -> 0 | S22: =R$20/R$27 -> #DIV/0! | T22: =SUM(T21) -> 0 | U22: =T$20/T$27 -> #DIV/0! | V22: =SUM(P22,R22,T22) -> 0 | X22: =SUM(X21) -> 0 | Y22: =X$20/X$27 -> #DIV/0! | Z22: =SUM(Z21) -> 0 | AA22: =Z$20/Z$27 -> #DIV/0! | AB22: =SUM(AB21) -> 0 | AC22: =AB$20/AB$27 -> #DIV/0! | AD22: =SUM(X22,Z22,AB22) -> 0 | AF22: =SUM(AF21) -> 0 | AG22: =AF$20/AF$27 -> #DIV/0! | AH22: =SUM(AH21) -> 0 | AI22: =AH$20/AH$27 -> #DIV/0! | AJ22: =SUM(AJ21) -> 0 | AK22: =AJ$20/AJ$27 -> #DIV/0! | AL22: =SUM(AF22,AH22,AJ22) -> 0 | AN22: =SUM(AN21) -> 33747760
F23: 일산중심재활병원 | G23: 일반세탁물 | H23: 0 | I23: =H23/H$27 -> 0 | J23: 490909 | K23: =J23/J$27 -> 0.006655254 | L23: =4818182+490909 -> 5309091 | M23: =L23/L$27 -> 0.052224004 | N23: =SUM(H23,J23,L23) -> 5800000 | O23: =N23/N$27 -> 0.02228613 | Q23: =P23/P$27 -> #DIV/0! | S23: =R23/R$27 -> #DIV/0! | U23: =T23/T$27 -> #DIV/0! | V23: =SUM(P23,R23,T23) -> 0 | W23: =V23/V$27 -> #DIV/0! | Y23: =X23/X$27 -> #DIV/0! | AA23: =Z23/Z$27 -> #DIV/0! | AC23: =AB23/AB$27 -> #DIV/0! | AD23: =SUM(X23,Z23,AB23) -> 0 | AE23: =AD23/AD$27 -> #DIV/0! | AG23: =AF23/AF$27 -> #DIV/0! | AI23: =AH23/AH$27 -> #DIV/0! | AK23: =AJ23/AJ$27 -> #DIV/0! | AL23: =SUM(AF23,AH23,AJ23) -> 0 | AM23: =AL23/AL$27 -> #DIV/0! | AN23: =SUM(N23+V23+AD23+AL23) -> 5800000
G24: 일산중심재활병원 매출 합계 | H24: =SUM(H23) -> 0 | I24: =H24/H$27 -> 0 | J24: =SUM(J23) -> 490909 | K24: =J24/J$27 -> 0.006655254 | L24: =SUM(L23) -> 5309091 | M24: =L24/L$27 -> 0.052224004 | N24: =SUM(H24,J24,L24) -> 5800000 | O24: =N24/N$27 -> 0.02228613 | P24: =SUM(P23) -> 0 | Q24: =P$20/P$27 -> #DIV/0! | R24: =SUM(R23) -> 0 | S24: =R$20/R$27 -> #DIV/0! | T24: =SUM(T23) -> 0 | U24: =T$20/T$27 -> #DIV/0! | V24: =SUM(P24,R24,T24) -> 0 | X24: =SUM(X23) -> 0 | Y24: =X$20/X$27 -> #DIV/0! | Z24: =SUM(Z23) -> 0 | AA24: =Z$20/Z$27 -> #DIV/0! | AB24: =SUM(AB23) -> 0 | AC24: =AB$20/AB$27 -> #DIV/0! | AD24: =SUM(X24,Z24,AB24) -> 0 | AF24: =SUM(AF23) -> 0 | AG24: =AF$20/AF$27 -> #DIV/0! | AH24: =SUM(AH23) -> 0 | AI24: =AH$20/AH$27 -> #DIV/0! | AJ24: =SUM(AJ23) -> 0 | AK24: =AJ$20/AJ$27 -> #DIV/0! | AL24: =SUM(AF24,AH24,AJ24) -> 0 | AN24: =SUM(AN23) -> 5800000
